[2024-06-30T09:20:52.413+0000] {processor.py:153} INFO - Started process (PID=182) to work on /opt/airflow/dags/P2M3_devi_nirfana_DAG.py
[2024-06-30T09:20:52.415+0000] {processor.py:640} INFO - Processing file /opt/airflow/dags/P2M3_devi_nirfana_DAG.py for tasks to queue
[2024-06-30T09:20:52.416+0000] {logging_mixin.py:115} INFO - [2024-06-30T09:20:52.416+0000] {dagbag.py:508} INFO - Filling up the DagBag from /opt/airflow/dags/P2M3_devi_nirfana_DAG.py
[2024-06-30T09:20:53.045+0000] {processor.py:650} INFO - DAG(s) dict_keys(['Milestones3']) retrieved from /opt/airflow/dags/P2M3_devi_nirfana_DAG.py
[2024-06-30T09:20:53.134+0000] {logging_mixin.py:115} INFO - [2024-06-30T09:20:53.134+0000] {manager.py:508} INFO - Created Permission View: can read on DAG:Milestones3
[2024-06-30T09:20:53.148+0000] {logging_mixin.py:115} INFO - [2024-06-30T09:20:53.148+0000] {manager.py:508} INFO - Created Permission View: can edit on DAG:Milestones3
[2024-06-30T09:20:53.158+0000] {logging_mixin.py:115} INFO - [2024-06-30T09:20:53.158+0000] {manager.py:508} INFO - Created Permission View: can delete on DAG:Milestones3
[2024-06-30T09:20:53.159+0000] {logging_mixin.py:115} INFO - [2024-06-30T09:20:53.159+0000] {dag.py:2429} INFO - Sync 1 DAGs
[2024-06-30T09:20:53.168+0000] {logging_mixin.py:115} INFO - [2024-06-30T09:20:53.168+0000] {dag.py:2448} INFO - Creating ORM DAG for Milestones3
[2024-06-30T09:20:53.184+0000] {logging_mixin.py:115} INFO - [2024-06-30T09:20:53.184+0000] {dag.py:2981} INFO - Setting next_dagrun for Milestones3 to 2024-06-19T06:30:00+00:00, run_after=2024-06-20T06:30:00+00:00
[2024-06-30T09:20:53.201+0000] {processor.py:161} INFO - Processing /opt/airflow/dags/P2M3_devi_nirfana_DAG.py took 0.795 seconds
[2024-06-30T09:20:58.247+0000] {processor.py:153} INFO - Started process (PID=189) to work on /opt/airflow/dags/P2M3_devi_nirfana_DAG.py
[2024-06-30T09:20:58.250+0000] {processor.py:640} INFO - Processing file /opt/airflow/dags/P2M3_devi_nirfana_DAG.py for tasks to queue
[2024-06-30T09:20:58.251+0000] {logging_mixin.py:115} INFO - [2024-06-30T09:20:58.251+0000] {dagbag.py:508} INFO - Filling up the DagBag from /opt/airflow/dags/P2M3_devi_nirfana_DAG.py
[2024-06-30T09:20:58.990+0000] {processor.py:650} INFO - DAG(s) dict_keys(['Milestones3']) retrieved from /opt/airflow/dags/P2M3_devi_nirfana_DAG.py
[2024-06-30T09:20:59.011+0000] {logging_mixin.py:115} INFO - [2024-06-30T09:20:59.010+0000] {dag.py:2429} INFO - Sync 1 DAGs
[2024-06-30T09:20:59.035+0000] {logging_mixin.py:115} INFO - [2024-06-30T09:20:59.034+0000] {dag.py:2981} INFO - Setting next_dagrun for Milestones3 to 2024-06-19T06:30:00+00:00, run_after=2024-06-20T06:30:00+00:00
[2024-06-30T09:20:59.050+0000] {processor.py:161} INFO - Processing /opt/airflow/dags/P2M3_devi_nirfana_DAG.py took 0.810 seconds
[2024-06-30T09:21:04.095+0000] {processor.py:153} INFO - Started process (PID=195) to work on /opt/airflow/dags/P2M3_devi_nirfana_DAG.py
[2024-06-30T09:21:04.096+0000] {processor.py:640} INFO - Processing file /opt/airflow/dags/P2M3_devi_nirfana_DAG.py for tasks to queue
[2024-06-30T09:21:04.098+0000] {logging_mixin.py:115} INFO - [2024-06-30T09:21:04.097+0000] {dagbag.py:508} INFO - Filling up the DagBag from /opt/airflow/dags/P2M3_devi_nirfana_DAG.py
[2024-06-30T09:21:04.672+0000] {processor.py:650} INFO - DAG(s) dict_keys(['Milestones3']) retrieved from /opt/airflow/dags/P2M3_devi_nirfana_DAG.py
[2024-06-30T09:21:04.701+0000] {logging_mixin.py:115} INFO - [2024-06-30T09:21:04.700+0000] {dag.py:2429} INFO - Sync 1 DAGs
[2024-06-30T09:21:04.742+0000] {logging_mixin.py:115} INFO - [2024-06-30T09:21:04.741+0000] {dag.py:2981} INFO - Setting next_dagrun for Milestones3 to 2024-06-19T06:30:00+00:00, run_after=2024-06-20T06:30:00+00:00
[2024-06-30T09:21:04.766+0000] {processor.py:161} INFO - Processing /opt/airflow/dags/P2M3_devi_nirfana_DAG.py took 0.675 seconds
[2024-06-30T09:21:34.880+0000] {processor.py:153} INFO - Started process (PID=201) to work on /opt/airflow/dags/P2M3_devi_nirfana_DAG.py
[2024-06-30T09:21:34.882+0000] {processor.py:640} INFO - Processing file /opt/airflow/dags/P2M3_devi_nirfana_DAG.py for tasks to queue
[2024-06-30T09:21:34.884+0000] {logging_mixin.py:115} INFO - [2024-06-30T09:21:34.884+0000] {dagbag.py:508} INFO - Filling up the DagBag from /opt/airflow/dags/P2M3_devi_nirfana_DAG.py
[2024-06-30T09:21:35.263+0000] {processor.py:650} INFO - DAG(s) dict_keys(['Milestones3']) retrieved from /opt/airflow/dags/P2M3_devi_nirfana_DAG.py
[2024-06-30T09:21:35.285+0000] {logging_mixin.py:115} INFO - [2024-06-30T09:21:35.285+0000] {dag.py:2429} INFO - Sync 1 DAGs
[2024-06-30T09:21:35.302+0000] {logging_mixin.py:115} INFO - [2024-06-30T09:21:35.302+0000] {dag.py:2981} INFO - Setting next_dagrun for Milestones3 to 2024-06-19T06:30:00+00:00, run_after=2024-06-20T06:30:00+00:00
[2024-06-30T09:21:35.314+0000] {processor.py:161} INFO - Processing /opt/airflow/dags/P2M3_devi_nirfana_DAG.py took 0.438 seconds
[2024-06-30T09:21:52.962+0000] {processor.py:153} INFO - Started process (PID=207) to work on /opt/airflow/dags/P2M3_devi_nirfana_DAG.py
[2024-06-30T09:21:52.963+0000] {processor.py:640} INFO - Processing file /opt/airflow/dags/P2M3_devi_nirfana_DAG.py for tasks to queue
[2024-06-30T09:21:52.964+0000] {logging_mixin.py:115} INFO - [2024-06-30T09:21:52.964+0000] {dagbag.py:508} INFO - Filling up the DagBag from /opt/airflow/dags/P2M3_devi_nirfana_DAG.py
[2024-06-30T09:21:53.355+0000] {processor.py:650} INFO - DAG(s) dict_keys(['Milestones3']) retrieved from /opt/airflow/dags/P2M3_devi_nirfana_DAG.py
[2024-06-30T09:21:53.376+0000] {logging_mixin.py:115} INFO - [2024-06-30T09:21:53.375+0000] {dag.py:2429} INFO - Sync 1 DAGs
[2024-06-30T09:21:53.394+0000] {logging_mixin.py:115} INFO - [2024-06-30T09:21:53.394+0000] {dag.py:2981} INFO - Setting next_dagrun for Milestones3 to 2024-06-19T06:30:00+00:00, run_after=2024-06-20T06:30:00+00:00
[2024-06-30T09:21:53.408+0000] {processor.py:161} INFO - Processing /opt/airflow/dags/P2M3_devi_nirfana_DAG.py took 0.450 seconds
[2024-06-30T09:21:58.423+0000] {processor.py:153} INFO - Started process (PID=213) to work on /opt/airflow/dags/P2M3_devi_nirfana_DAG.py
[2024-06-30T09:21:58.425+0000] {processor.py:640} INFO - Processing file /opt/airflow/dags/P2M3_devi_nirfana_DAG.py for tasks to queue
[2024-06-30T09:21:58.426+0000] {logging_mixin.py:115} INFO - [2024-06-30T09:21:58.426+0000] {dagbag.py:508} INFO - Filling up the DagBag from /opt/airflow/dags/P2M3_devi_nirfana_DAG.py
[2024-06-30T09:21:58.809+0000] {processor.py:650} INFO - DAG(s) dict_keys(['Milestones3']) retrieved from /opt/airflow/dags/P2M3_devi_nirfana_DAG.py
[2024-06-30T09:21:58.836+0000] {logging_mixin.py:115} INFO - [2024-06-30T09:21:58.834+0000] {dag.py:2429} INFO - Sync 1 DAGs
[2024-06-30T09:21:58.860+0000] {logging_mixin.py:115} INFO - [2024-06-30T09:21:58.860+0000] {dag.py:2981} INFO - Setting next_dagrun for Milestones3 to 2024-06-19T06:30:00+00:00, run_after=2024-06-20T06:30:00+00:00
[2024-06-30T09:21:58.877+0000] {processor.py:161} INFO - Processing /opt/airflow/dags/P2M3_devi_nirfana_DAG.py took 0.459 seconds
[2024-06-30T09:22:01.918+0000] {processor.py:153} INFO - Started process (PID=219) to work on /opt/airflow/dags/P2M3_devi_nirfana_DAG.py
[2024-06-30T09:22:01.919+0000] {processor.py:640} INFO - Processing file /opt/airflow/dags/P2M3_devi_nirfana_DAG.py for tasks to queue
[2024-06-30T09:22:01.921+0000] {logging_mixin.py:115} INFO - [2024-06-30T09:22:01.921+0000] {dagbag.py:508} INFO - Filling up the DagBag from /opt/airflow/dags/P2M3_devi_nirfana_DAG.py
[2024-06-30T09:22:02.351+0000] {processor.py:650} INFO - DAG(s) dict_keys(['Milestones3']) retrieved from /opt/airflow/dags/P2M3_devi_nirfana_DAG.py
[2024-06-30T09:22:02.373+0000] {logging_mixin.py:115} INFO - [2024-06-30T09:22:02.373+0000] {dag.py:2429} INFO - Sync 1 DAGs
[2024-06-30T09:22:02.396+0000] {logging_mixin.py:115} INFO - [2024-06-30T09:22:02.395+0000] {dag.py:2981} INFO - Setting next_dagrun for Milestones3 to 2024-06-19T06:30:00+00:00, run_after=2024-06-20T06:30:00+00:00
[2024-06-30T09:22:02.411+0000] {processor.py:161} INFO - Processing /opt/airflow/dags/P2M3_devi_nirfana_DAG.py took 0.497 seconds
[2024-06-30T09:22:09.959+0000] {processor.py:153} INFO - Started process (PID=225) to work on /opt/airflow/dags/P2M3_devi_nirfana_DAG.py
[2024-06-30T09:22:09.961+0000] {processor.py:640} INFO - Processing file /opt/airflow/dags/P2M3_devi_nirfana_DAG.py for tasks to queue
[2024-06-30T09:22:09.962+0000] {logging_mixin.py:115} INFO - [2024-06-30T09:22:09.962+0000] {dagbag.py:508} INFO - Filling up the DagBag from /opt/airflow/dags/P2M3_devi_nirfana_DAG.py
[2024-06-30T09:22:10.398+0000] {logging_mixin.py:115} INFO - [2024-06-30T09:22:10.395+0000] {dagbag.py:321} ERROR - Failed to import: /opt/airflow/dags/P2M3_devi_nirfana_DAG.py
Traceback (most recent call last):
  File "/home/airflow/.local/lib/python3.7/site-packages/sqlalchemy/engine/base.py", line 3243, in _wrap_pool_connect
    return fn()
  File "/home/airflow/.local/lib/python3.7/site-packages/sqlalchemy/pool/base.py", line 310, in connect
    return _ConnectionFairy._checkout(self)
  File "/home/airflow/.local/lib/python3.7/site-packages/sqlalchemy/pool/base.py", line 868, in _checkout
    fairy = _ConnectionRecord.checkout(pool)
  File "/home/airflow/.local/lib/python3.7/site-packages/sqlalchemy/pool/base.py", line 476, in checkout
    rec = pool._do_get()
  File "/home/airflow/.local/lib/python3.7/site-packages/sqlalchemy/pool/impl.py", line 146, in _do_get
    self._dec_overflow()
  File "/home/airflow/.local/lib/python3.7/site-packages/sqlalchemy/util/langhelpers.py", line 72, in __exit__
    with_traceback=exc_tb,
  File "/home/airflow/.local/lib/python3.7/site-packages/sqlalchemy/util/compat.py", line 207, in raise_
    raise exception
  File "/home/airflow/.local/lib/python3.7/site-packages/sqlalchemy/pool/impl.py", line 143, in _do_get
    return self._create_connection()
  File "/home/airflow/.local/lib/python3.7/site-packages/sqlalchemy/pool/base.py", line 256, in _create_connection
    return _ConnectionRecord(self)
  File "/home/airflow/.local/lib/python3.7/site-packages/sqlalchemy/pool/base.py", line 371, in __init__
    self.__connect()
  File "/home/airflow/.local/lib/python3.7/site-packages/sqlalchemy/pool/base.py", line 666, in __connect
    pool.logger.debug("Error on connect(): %s", e)
  File "/home/airflow/.local/lib/python3.7/site-packages/sqlalchemy/util/langhelpers.py", line 72, in __exit__
    with_traceback=exc_tb,
  File "/home/airflow/.local/lib/python3.7/site-packages/sqlalchemy/util/compat.py", line 207, in raise_
    raise exception
  File "/home/airflow/.local/lib/python3.7/site-packages/sqlalchemy/pool/base.py", line 661, in __connect
    self.dbapi_connection = connection = pool._invoke_creator(self)
  File "/home/airflow/.local/lib/python3.7/site-packages/sqlalchemy/engine/create.py", line 590, in connect
    return dialect.connect(*cargs, **cparams)
  File "/home/airflow/.local/lib/python3.7/site-packages/sqlalchemy/engine/default.py", line 584, in connect
    return self.dbapi.connect(*cargs, **cparams)
  File "/home/airflow/.local/lib/python3.7/site-packages/psycopg2/__init__.py", line 122, in connect
    conn = _connect(dsn, connection_factory=connection_factory, **kwasync)
psycopg2.OperationalError: connection to server at "postgres" (172.18.0.3), port 5432 failed: FATAL:  database "airflow" does not exist


The above exception was the direct cause of the following exception:

Traceback (most recent call last):
  File "/home/airflow/.local/lib/python3.7/site-packages/airflow/models/dagbag.py", line 318, in parse
    loader.exec_module(new_module)
  File "<frozen importlib._bootstrap_external>", line 728, in exec_module
  File "<frozen importlib._bootstrap>", line 219, in _call_with_frames_removed
  File "/opt/airflow/dags/P2M3_devi_nirfana_DAG.py", line 28, in <module>
    conn = engine.connect()
  File "/home/airflow/.local/lib/python3.7/site-packages/sqlalchemy/engine/base.py", line 3197, in connect
    return self._connection_cls(self, close_with_result=close_with_result)
  File "/home/airflow/.local/lib/python3.7/site-packages/sqlalchemy/engine/base.py", line 96, in __init__
    else engine.raw_connection()
  File "/home/airflow/.local/lib/python3.7/site-packages/sqlalchemy/engine/base.py", line 3276, in raw_connection
    return self._wrap_pool_connect(self.pool.connect, _connection)
  File "/home/airflow/.local/lib/python3.7/site-packages/sqlalchemy/engine/base.py", line 3247, in _wrap_pool_connect
    e, dialect, self
  File "/home/airflow/.local/lib/python3.7/site-packages/sqlalchemy/engine/base.py", line 2101, in _handle_dbapi_exception_noconnection
    sqlalchemy_exception, with_traceback=exc_info[2], from_=e
  File "/home/airflow/.local/lib/python3.7/site-packages/sqlalchemy/util/compat.py", line 207, in raise_
    raise exception
  File "/home/airflow/.local/lib/python3.7/site-packages/sqlalchemy/engine/base.py", line 3243, in _wrap_pool_connect
    return fn()
  File "/home/airflow/.local/lib/python3.7/site-packages/sqlalchemy/pool/base.py", line 310, in connect
    return _ConnectionFairy._checkout(self)
  File "/home/airflow/.local/lib/python3.7/site-packages/sqlalchemy/pool/base.py", line 868, in _checkout
    fairy = _ConnectionRecord.checkout(pool)
  File "/home/airflow/.local/lib/python3.7/site-packages/sqlalchemy/pool/base.py", line 476, in checkout
    rec = pool._do_get()
  File "/home/airflow/.local/lib/python3.7/site-packages/sqlalchemy/pool/impl.py", line 146, in _do_get
    self._dec_overflow()
  File "/home/airflow/.local/lib/python3.7/site-packages/sqlalchemy/util/langhelpers.py", line 72, in __exit__
    with_traceback=exc_tb,
  File "/home/airflow/.local/lib/python3.7/site-packages/sqlalchemy/util/compat.py", line 207, in raise_
    raise exception
  File "/home/airflow/.local/lib/python3.7/site-packages/sqlalchemy/pool/impl.py", line 143, in _do_get
    return self._create_connection()
  File "/home/airflow/.local/lib/python3.7/site-packages/sqlalchemy/pool/base.py", line 256, in _create_connection
    return _ConnectionRecord(self)
  File "/home/airflow/.local/lib/python3.7/site-packages/sqlalchemy/pool/base.py", line 371, in __init__
    self.__connect()
  File "/home/airflow/.local/lib/python3.7/site-packages/sqlalchemy/pool/base.py", line 666, in __connect
    pool.logger.debug("Error on connect(): %s", e)
  File "/home/airflow/.local/lib/python3.7/site-packages/sqlalchemy/util/langhelpers.py", line 72, in __exit__
    with_traceback=exc_tb,
  File "/home/airflow/.local/lib/python3.7/site-packages/sqlalchemy/util/compat.py", line 207, in raise_
    raise exception
  File "/home/airflow/.local/lib/python3.7/site-packages/sqlalchemy/pool/base.py", line 661, in __connect
    self.dbapi_connection = connection = pool._invoke_creator(self)
  File "/home/airflow/.local/lib/python3.7/site-packages/sqlalchemy/engine/create.py", line 590, in connect
    return dialect.connect(*cargs, **cparams)
  File "/home/airflow/.local/lib/python3.7/site-packages/sqlalchemy/engine/default.py", line 584, in connect
    return self.dbapi.connect(*cargs, **cparams)
  File "/home/airflow/.local/lib/python3.7/site-packages/psycopg2/__init__.py", line 122, in connect
    conn = _connect(dsn, connection_factory=connection_factory, **kwasync)
sqlalchemy.exc.OperationalError: (psycopg2.OperationalError) connection to server at "postgres" (172.18.0.3), port 5432 failed: FATAL:  database "airflow" does not exist

(Background on this error at: https://sqlalche.me/e/14/e3q8)
[2024-06-30T09:22:10.400+0000] {processor.py:652} WARNING - No viable dags retrieved from /opt/airflow/dags/P2M3_devi_nirfana_DAG.py
[2024-06-30T09:22:10.422+0000] {processor.py:161} INFO - Processing /opt/airflow/dags/P2M3_devi_nirfana_DAG.py took 0.467 seconds
[2024-06-30T09:22:12.470+0000] {processor.py:153} INFO - Started process (PID=231) to work on /opt/airflow/dags/P2M3_devi_nirfana_DAG.py
[2024-06-30T09:22:12.471+0000] {processor.py:640} INFO - Processing file /opt/airflow/dags/P2M3_devi_nirfana_DAG.py for tasks to queue
[2024-06-30T09:22:12.472+0000] {logging_mixin.py:115} INFO - [2024-06-30T09:22:12.472+0000] {dagbag.py:508} INFO - Filling up the DagBag from /opt/airflow/dags/P2M3_devi_nirfana_DAG.py
[2024-06-30T09:22:13.010+0000] {logging_mixin.py:115} INFO - [2024-06-30T09:22:13.007+0000] {dagbag.py:321} ERROR - Failed to import: /opt/airflow/dags/P2M3_devi_nirfana_DAG.py
Traceback (most recent call last):
  File "/home/airflow/.local/lib/python3.7/site-packages/sqlalchemy/engine/base.py", line 3243, in _wrap_pool_connect
    return fn()
  File "/home/airflow/.local/lib/python3.7/site-packages/sqlalchemy/pool/base.py", line 310, in connect
    return _ConnectionFairy._checkout(self)
  File "/home/airflow/.local/lib/python3.7/site-packages/sqlalchemy/pool/base.py", line 868, in _checkout
    fairy = _ConnectionRecord.checkout(pool)
  File "/home/airflow/.local/lib/python3.7/site-packages/sqlalchemy/pool/base.py", line 476, in checkout
    rec = pool._do_get()
  File "/home/airflow/.local/lib/python3.7/site-packages/sqlalchemy/pool/impl.py", line 146, in _do_get
    self._dec_overflow()
  File "/home/airflow/.local/lib/python3.7/site-packages/sqlalchemy/util/langhelpers.py", line 72, in __exit__
    with_traceback=exc_tb,
  File "/home/airflow/.local/lib/python3.7/site-packages/sqlalchemy/util/compat.py", line 207, in raise_
    raise exception
  File "/home/airflow/.local/lib/python3.7/site-packages/sqlalchemy/pool/impl.py", line 143, in _do_get
    return self._create_connection()
  File "/home/airflow/.local/lib/python3.7/site-packages/sqlalchemy/pool/base.py", line 256, in _create_connection
    return _ConnectionRecord(self)
  File "/home/airflow/.local/lib/python3.7/site-packages/sqlalchemy/pool/base.py", line 371, in __init__
    self.__connect()
  File "/home/airflow/.local/lib/python3.7/site-packages/sqlalchemy/pool/base.py", line 666, in __connect
    pool.logger.debug("Error on connect(): %s", e)
  File "/home/airflow/.local/lib/python3.7/site-packages/sqlalchemy/util/langhelpers.py", line 72, in __exit__
    with_traceback=exc_tb,
  File "/home/airflow/.local/lib/python3.7/site-packages/sqlalchemy/util/compat.py", line 207, in raise_
    raise exception
  File "/home/airflow/.local/lib/python3.7/site-packages/sqlalchemy/pool/base.py", line 661, in __connect
    self.dbapi_connection = connection = pool._invoke_creator(self)
  File "/home/airflow/.local/lib/python3.7/site-packages/sqlalchemy/engine/create.py", line 590, in connect
    return dialect.connect(*cargs, **cparams)
  File "/home/airflow/.local/lib/python3.7/site-packages/sqlalchemy/engine/default.py", line 584, in connect
    return self.dbapi.connect(*cargs, **cparams)
  File "/home/airflow/.local/lib/python3.7/site-packages/psycopg2/__init__.py", line 122, in connect
    conn = _connect(dsn, connection_factory=connection_factory, **kwasync)
psycopg2.OperationalError: connection to server at "postgres" (172.18.0.3), port 5432 failed: FATAL:  password authentication failed for user "airflow"


The above exception was the direct cause of the following exception:

Traceback (most recent call last):
  File "/home/airflow/.local/lib/python3.7/site-packages/airflow/models/dagbag.py", line 318, in parse
    loader.exec_module(new_module)
  File "<frozen importlib._bootstrap_external>", line 728, in exec_module
  File "<frozen importlib._bootstrap>", line 219, in _call_with_frames_removed
  File "/opt/airflow/dags/P2M3_devi_nirfana_DAG.py", line 28, in <module>
    conn = engine.connect()
  File "/home/airflow/.local/lib/python3.7/site-packages/sqlalchemy/engine/base.py", line 3197, in connect
    return self._connection_cls(self, close_with_result=close_with_result)
  File "/home/airflow/.local/lib/python3.7/site-packages/sqlalchemy/engine/base.py", line 96, in __init__
    else engine.raw_connection()
  File "/home/airflow/.local/lib/python3.7/site-packages/sqlalchemy/engine/base.py", line 3276, in raw_connection
    return self._wrap_pool_connect(self.pool.connect, _connection)
  File "/home/airflow/.local/lib/python3.7/site-packages/sqlalchemy/engine/base.py", line 3247, in _wrap_pool_connect
    e, dialect, self
  File "/home/airflow/.local/lib/python3.7/site-packages/sqlalchemy/engine/base.py", line 2101, in _handle_dbapi_exception_noconnection
    sqlalchemy_exception, with_traceback=exc_info[2], from_=e
  File "/home/airflow/.local/lib/python3.7/site-packages/sqlalchemy/util/compat.py", line 207, in raise_
    raise exception
  File "/home/airflow/.local/lib/python3.7/site-packages/sqlalchemy/engine/base.py", line 3243, in _wrap_pool_connect
    return fn()
  File "/home/airflow/.local/lib/python3.7/site-packages/sqlalchemy/pool/base.py", line 310, in connect
    return _ConnectionFairy._checkout(self)
  File "/home/airflow/.local/lib/python3.7/site-packages/sqlalchemy/pool/base.py", line 868, in _checkout
    fairy = _ConnectionRecord.checkout(pool)
  File "/home/airflow/.local/lib/python3.7/site-packages/sqlalchemy/pool/base.py", line 476, in checkout
    rec = pool._do_get()
  File "/home/airflow/.local/lib/python3.7/site-packages/sqlalchemy/pool/impl.py", line 146, in _do_get
    self._dec_overflow()
  File "/home/airflow/.local/lib/python3.7/site-packages/sqlalchemy/util/langhelpers.py", line 72, in __exit__
    with_traceback=exc_tb,
  File "/home/airflow/.local/lib/python3.7/site-packages/sqlalchemy/util/compat.py", line 207, in raise_
    raise exception
  File "/home/airflow/.local/lib/python3.7/site-packages/sqlalchemy/pool/impl.py", line 143, in _do_get
    return self._create_connection()
  File "/home/airflow/.local/lib/python3.7/site-packages/sqlalchemy/pool/base.py", line 256, in _create_connection
    return _ConnectionRecord(self)
  File "/home/airflow/.local/lib/python3.7/site-packages/sqlalchemy/pool/base.py", line 371, in __init__
    self.__connect()
  File "/home/airflow/.local/lib/python3.7/site-packages/sqlalchemy/pool/base.py", line 666, in __connect
    pool.logger.debug("Error on connect(): %s", e)
  File "/home/airflow/.local/lib/python3.7/site-packages/sqlalchemy/util/langhelpers.py", line 72, in __exit__
    with_traceback=exc_tb,
  File "/home/airflow/.local/lib/python3.7/site-packages/sqlalchemy/util/compat.py", line 207, in raise_
    raise exception
  File "/home/airflow/.local/lib/python3.7/site-packages/sqlalchemy/pool/base.py", line 661, in __connect
    self.dbapi_connection = connection = pool._invoke_creator(self)
  File "/home/airflow/.local/lib/python3.7/site-packages/sqlalchemy/engine/create.py", line 590, in connect
    return dialect.connect(*cargs, **cparams)
  File "/home/airflow/.local/lib/python3.7/site-packages/sqlalchemy/engine/default.py", line 584, in connect
    return self.dbapi.connect(*cargs, **cparams)
  File "/home/airflow/.local/lib/python3.7/site-packages/psycopg2/__init__.py", line 122, in connect
    conn = _connect(dsn, connection_factory=connection_factory, **kwasync)
sqlalchemy.exc.OperationalError: (psycopg2.OperationalError) connection to server at "postgres" (172.18.0.3), port 5432 failed: FATAL:  password authentication failed for user "airflow"

(Background on this error at: https://sqlalche.me/e/14/e3q8)
[2024-06-30T09:22:13.012+0000] {processor.py:652} WARNING - No viable dags retrieved from /opt/airflow/dags/P2M3_devi_nirfana_DAG.py
[2024-06-30T09:22:13.033+0000] {processor.py:161} INFO - Processing /opt/airflow/dags/P2M3_devi_nirfana_DAG.py took 0.566 seconds
[2024-06-30T09:22:15.486+0000] {processor.py:153} INFO - Started process (PID=237) to work on /opt/airflow/dags/P2M3_devi_nirfana_DAG.py
[2024-06-30T09:22:15.488+0000] {processor.py:640} INFO - Processing file /opt/airflow/dags/P2M3_devi_nirfana_DAG.py for tasks to queue
[2024-06-30T09:22:15.508+0000] {logging_mixin.py:115} INFO - [2024-06-30T09:22:15.507+0000] {dagbag.py:508} INFO - Filling up the DagBag from /opt/airflow/dags/P2M3_devi_nirfana_DAG.py
[2024-06-30T09:22:15.905+0000] {logging_mixin.py:115} INFO - [2024-06-30T09:22:15.901+0000] {dagbag.py:321} ERROR - Failed to import: /opt/airflow/dags/P2M3_devi_nirfana_DAG.py
Traceback (most recent call last):
  File "/home/airflow/.local/lib/python3.7/site-packages/sqlalchemy/engine/base.py", line 3243, in _wrap_pool_connect
    return fn()
  File "/home/airflow/.local/lib/python3.7/site-packages/sqlalchemy/pool/base.py", line 310, in connect
    return _ConnectionFairy._checkout(self)
  File "/home/airflow/.local/lib/python3.7/site-packages/sqlalchemy/pool/base.py", line 868, in _checkout
    fairy = _ConnectionRecord.checkout(pool)
  File "/home/airflow/.local/lib/python3.7/site-packages/sqlalchemy/pool/base.py", line 476, in checkout
    rec = pool._do_get()
  File "/home/airflow/.local/lib/python3.7/site-packages/sqlalchemy/pool/impl.py", line 146, in _do_get
    self._dec_overflow()
  File "/home/airflow/.local/lib/python3.7/site-packages/sqlalchemy/util/langhelpers.py", line 72, in __exit__
    with_traceback=exc_tb,
  File "/home/airflow/.local/lib/python3.7/site-packages/sqlalchemy/util/compat.py", line 207, in raise_
    raise exception
  File "/home/airflow/.local/lib/python3.7/site-packages/sqlalchemy/pool/impl.py", line 143, in _do_get
    return self._create_connection()
  File "/home/airflow/.local/lib/python3.7/site-packages/sqlalchemy/pool/base.py", line 256, in _create_connection
    return _ConnectionRecord(self)
  File "/home/airflow/.local/lib/python3.7/site-packages/sqlalchemy/pool/base.py", line 371, in __init__
    self.__connect()
  File "/home/airflow/.local/lib/python3.7/site-packages/sqlalchemy/pool/base.py", line 666, in __connect
    pool.logger.debug("Error on connect(): %s", e)
  File "/home/airflow/.local/lib/python3.7/site-packages/sqlalchemy/util/langhelpers.py", line 72, in __exit__
    with_traceback=exc_tb,
  File "/home/airflow/.local/lib/python3.7/site-packages/sqlalchemy/util/compat.py", line 207, in raise_
    raise exception
  File "/home/airflow/.local/lib/python3.7/site-packages/sqlalchemy/pool/base.py", line 661, in __connect
    self.dbapi_connection = connection = pool._invoke_creator(self)
  File "/home/airflow/.local/lib/python3.7/site-packages/sqlalchemy/engine/create.py", line 590, in connect
    return dialect.connect(*cargs, **cparams)
  File "/home/airflow/.local/lib/python3.7/site-packages/sqlalchemy/engine/default.py", line 584, in connect
    return self.dbapi.connect(*cargs, **cparams)
  File "/home/airflow/.local/lib/python3.7/site-packages/psycopg2/__init__.py", line 122, in connect
    conn = _connect(dsn, connection_factory=connection_factory, **kwasync)
psycopg2.OperationalError: connection to server at "postgres" (172.18.0.3), port 5432 failed: FATAL:  password authentication failed for user "airflow"


The above exception was the direct cause of the following exception:

Traceback (most recent call last):
  File "/home/airflow/.local/lib/python3.7/site-packages/airflow/models/dagbag.py", line 318, in parse
    loader.exec_module(new_module)
  File "<frozen importlib._bootstrap_external>", line 728, in exec_module
  File "<frozen importlib._bootstrap>", line 219, in _call_with_frames_removed
  File "/opt/airflow/dags/P2M3_devi_nirfana_DAG.py", line 28, in <module>
    conn = engine.connect()
  File "/home/airflow/.local/lib/python3.7/site-packages/sqlalchemy/engine/base.py", line 3197, in connect
    return self._connection_cls(self, close_with_result=close_with_result)
  File "/home/airflow/.local/lib/python3.7/site-packages/sqlalchemy/engine/base.py", line 96, in __init__
    else engine.raw_connection()
  File "/home/airflow/.local/lib/python3.7/site-packages/sqlalchemy/engine/base.py", line 3276, in raw_connection
    return self._wrap_pool_connect(self.pool.connect, _connection)
  File "/home/airflow/.local/lib/python3.7/site-packages/sqlalchemy/engine/base.py", line 3247, in _wrap_pool_connect
    e, dialect, self
  File "/home/airflow/.local/lib/python3.7/site-packages/sqlalchemy/engine/base.py", line 2101, in _handle_dbapi_exception_noconnection
    sqlalchemy_exception, with_traceback=exc_info[2], from_=e
  File "/home/airflow/.local/lib/python3.7/site-packages/sqlalchemy/util/compat.py", line 207, in raise_
    raise exception
  File "/home/airflow/.local/lib/python3.7/site-packages/sqlalchemy/engine/base.py", line 3243, in _wrap_pool_connect
    return fn()
  File "/home/airflow/.local/lib/python3.7/site-packages/sqlalchemy/pool/base.py", line 310, in connect
    return _ConnectionFairy._checkout(self)
  File "/home/airflow/.local/lib/python3.7/site-packages/sqlalchemy/pool/base.py", line 868, in _checkout
    fairy = _ConnectionRecord.checkout(pool)
  File "/home/airflow/.local/lib/python3.7/site-packages/sqlalchemy/pool/base.py", line 476, in checkout
    rec = pool._do_get()
  File "/home/airflow/.local/lib/python3.7/site-packages/sqlalchemy/pool/impl.py", line 146, in _do_get
    self._dec_overflow()
  File "/home/airflow/.local/lib/python3.7/site-packages/sqlalchemy/util/langhelpers.py", line 72, in __exit__
    with_traceback=exc_tb,
  File "/home/airflow/.local/lib/python3.7/site-packages/sqlalchemy/util/compat.py", line 207, in raise_
    raise exception
  File "/home/airflow/.local/lib/python3.7/site-packages/sqlalchemy/pool/impl.py", line 143, in _do_get
    return self._create_connection()
  File "/home/airflow/.local/lib/python3.7/site-packages/sqlalchemy/pool/base.py", line 256, in _create_connection
    return _ConnectionRecord(self)
  File "/home/airflow/.local/lib/python3.7/site-packages/sqlalchemy/pool/base.py", line 371, in __init__
    self.__connect()
  File "/home/airflow/.local/lib/python3.7/site-packages/sqlalchemy/pool/base.py", line 666, in __connect
    pool.logger.debug("Error on connect(): %s", e)
  File "/home/airflow/.local/lib/python3.7/site-packages/sqlalchemy/util/langhelpers.py", line 72, in __exit__
    with_traceback=exc_tb,
  File "/home/airflow/.local/lib/python3.7/site-packages/sqlalchemy/util/compat.py", line 207, in raise_
    raise exception
  File "/home/airflow/.local/lib/python3.7/site-packages/sqlalchemy/pool/base.py", line 661, in __connect
    self.dbapi_connection = connection = pool._invoke_creator(self)
  File "/home/airflow/.local/lib/python3.7/site-packages/sqlalchemy/engine/create.py", line 590, in connect
    return dialect.connect(*cargs, **cparams)
  File "/home/airflow/.local/lib/python3.7/site-packages/sqlalchemy/engine/default.py", line 584, in connect
    return self.dbapi.connect(*cargs, **cparams)
  File "/home/airflow/.local/lib/python3.7/site-packages/psycopg2/__init__.py", line 122, in connect
    conn = _connect(dsn, connection_factory=connection_factory, **kwasync)
sqlalchemy.exc.OperationalError: (psycopg2.OperationalError) connection to server at "postgres" (172.18.0.3), port 5432 failed: FATAL:  password authentication failed for user "airflow"

(Background on this error at: https://sqlalche.me/e/14/e3q8)
[2024-06-30T09:22:15.906+0000] {processor.py:652} WARNING - No viable dags retrieved from /opt/airflow/dags/P2M3_devi_nirfana_DAG.py
[2024-06-30T09:22:15.928+0000] {processor.py:161} INFO - Processing /opt/airflow/dags/P2M3_devi_nirfana_DAG.py took 0.446 seconds
[2024-06-30T09:22:30.006+0000] {processor.py:153} INFO - Started process (PID=243) to work on /opt/airflow/dags/P2M3_devi_nirfana_DAG.py
[2024-06-30T09:22:30.007+0000] {processor.py:640} INFO - Processing file /opt/airflow/dags/P2M3_devi_nirfana_DAG.py for tasks to queue
[2024-06-30T09:22:30.008+0000] {logging_mixin.py:115} INFO - [2024-06-30T09:22:30.008+0000] {dagbag.py:508} INFO - Filling up the DagBag from /opt/airflow/dags/P2M3_devi_nirfana_DAG.py
[2024-06-30T09:22:30.439+0000] {logging_mixin.py:115} INFO - [2024-06-30T09:22:30.436+0000] {dagbag.py:321} ERROR - Failed to import: /opt/airflow/dags/P2M3_devi_nirfana_DAG.py
Traceback (most recent call last):
  File "/home/airflow/.local/lib/python3.7/site-packages/sqlalchemy/engine/base.py", line 3243, in _wrap_pool_connect
    return fn()
  File "/home/airflow/.local/lib/python3.7/site-packages/sqlalchemy/pool/base.py", line 310, in connect
    return _ConnectionFairy._checkout(self)
  File "/home/airflow/.local/lib/python3.7/site-packages/sqlalchemy/pool/base.py", line 868, in _checkout
    fairy = _ConnectionRecord.checkout(pool)
  File "/home/airflow/.local/lib/python3.7/site-packages/sqlalchemy/pool/base.py", line 476, in checkout
    rec = pool._do_get()
  File "/home/airflow/.local/lib/python3.7/site-packages/sqlalchemy/pool/impl.py", line 146, in _do_get
    self._dec_overflow()
  File "/home/airflow/.local/lib/python3.7/site-packages/sqlalchemy/util/langhelpers.py", line 72, in __exit__
    with_traceback=exc_tb,
  File "/home/airflow/.local/lib/python3.7/site-packages/sqlalchemy/util/compat.py", line 207, in raise_
    raise exception
  File "/home/airflow/.local/lib/python3.7/site-packages/sqlalchemy/pool/impl.py", line 143, in _do_get
    return self._create_connection()
  File "/home/airflow/.local/lib/python3.7/site-packages/sqlalchemy/pool/base.py", line 256, in _create_connection
    return _ConnectionRecord(self)
  File "/home/airflow/.local/lib/python3.7/site-packages/sqlalchemy/pool/base.py", line 371, in __init__
    self.__connect()
  File "/home/airflow/.local/lib/python3.7/site-packages/sqlalchemy/pool/base.py", line 666, in __connect
    pool.logger.debug("Error on connect(): %s", e)
  File "/home/airflow/.local/lib/python3.7/site-packages/sqlalchemy/util/langhelpers.py", line 72, in __exit__
    with_traceback=exc_tb,
  File "/home/airflow/.local/lib/python3.7/site-packages/sqlalchemy/util/compat.py", line 207, in raise_
    raise exception
  File "/home/airflow/.local/lib/python3.7/site-packages/sqlalchemy/pool/base.py", line 661, in __connect
    self.dbapi_connection = connection = pool._invoke_creator(self)
  File "/home/airflow/.local/lib/python3.7/site-packages/sqlalchemy/engine/create.py", line 590, in connect
    return dialect.connect(*cargs, **cparams)
  File "/home/airflow/.local/lib/python3.7/site-packages/sqlalchemy/engine/default.py", line 584, in connect
    return self.dbapi.connect(*cargs, **cparams)
  File "/home/airflow/.local/lib/python3.7/site-packages/psycopg2/__init__.py", line 122, in connect
    conn = _connect(dsn, connection_factory=connection_factory, **kwasync)
psycopg2.OperationalError: connection to server at "postgres" (172.18.0.3), port 5432 failed: FATAL:  password authentication failed for user "airflow"


The above exception was the direct cause of the following exception:

Traceback (most recent call last):
  File "/home/airflow/.local/lib/python3.7/site-packages/airflow/models/dagbag.py", line 318, in parse
    loader.exec_module(new_module)
  File "<frozen importlib._bootstrap_external>", line 728, in exec_module
  File "<frozen importlib._bootstrap>", line 219, in _call_with_frames_removed
  File "/opt/airflow/dags/P2M3_devi_nirfana_DAG.py", line 28, in <module>
    conn = engine.connect()
  File "/home/airflow/.local/lib/python3.7/site-packages/sqlalchemy/engine/base.py", line 3197, in connect
    return self._connection_cls(self, close_with_result=close_with_result)
  File "/home/airflow/.local/lib/python3.7/site-packages/sqlalchemy/engine/base.py", line 96, in __init__
    else engine.raw_connection()
  File "/home/airflow/.local/lib/python3.7/site-packages/sqlalchemy/engine/base.py", line 3276, in raw_connection
    return self._wrap_pool_connect(self.pool.connect, _connection)
  File "/home/airflow/.local/lib/python3.7/site-packages/sqlalchemy/engine/base.py", line 3247, in _wrap_pool_connect
    e, dialect, self
  File "/home/airflow/.local/lib/python3.7/site-packages/sqlalchemy/engine/base.py", line 2101, in _handle_dbapi_exception_noconnection
    sqlalchemy_exception, with_traceback=exc_info[2], from_=e
  File "/home/airflow/.local/lib/python3.7/site-packages/sqlalchemy/util/compat.py", line 207, in raise_
    raise exception
  File "/home/airflow/.local/lib/python3.7/site-packages/sqlalchemy/engine/base.py", line 3243, in _wrap_pool_connect
    return fn()
  File "/home/airflow/.local/lib/python3.7/site-packages/sqlalchemy/pool/base.py", line 310, in connect
    return _ConnectionFairy._checkout(self)
  File "/home/airflow/.local/lib/python3.7/site-packages/sqlalchemy/pool/base.py", line 868, in _checkout
    fairy = _ConnectionRecord.checkout(pool)
  File "/home/airflow/.local/lib/python3.7/site-packages/sqlalchemy/pool/base.py", line 476, in checkout
    rec = pool._do_get()
  File "/home/airflow/.local/lib/python3.7/site-packages/sqlalchemy/pool/impl.py", line 146, in _do_get
    self._dec_overflow()
  File "/home/airflow/.local/lib/python3.7/site-packages/sqlalchemy/util/langhelpers.py", line 72, in __exit__
    with_traceback=exc_tb,
  File "/home/airflow/.local/lib/python3.7/site-packages/sqlalchemy/util/compat.py", line 207, in raise_
    raise exception
  File "/home/airflow/.local/lib/python3.7/site-packages/sqlalchemy/pool/impl.py", line 143, in _do_get
    return self._create_connection()
  File "/home/airflow/.local/lib/python3.7/site-packages/sqlalchemy/pool/base.py", line 256, in _create_connection
    return _ConnectionRecord(self)
  File "/home/airflow/.local/lib/python3.7/site-packages/sqlalchemy/pool/base.py", line 371, in __init__
    self.__connect()
  File "/home/airflow/.local/lib/python3.7/site-packages/sqlalchemy/pool/base.py", line 666, in __connect
    pool.logger.debug("Error on connect(): %s", e)
  File "/home/airflow/.local/lib/python3.7/site-packages/sqlalchemy/util/langhelpers.py", line 72, in __exit__
    with_traceback=exc_tb,
  File "/home/airflow/.local/lib/python3.7/site-packages/sqlalchemy/util/compat.py", line 207, in raise_
    raise exception
  File "/home/airflow/.local/lib/python3.7/site-packages/sqlalchemy/pool/base.py", line 661, in __connect
    self.dbapi_connection = connection = pool._invoke_creator(self)
  File "/home/airflow/.local/lib/python3.7/site-packages/sqlalchemy/engine/create.py", line 590, in connect
    return dialect.connect(*cargs, **cparams)
  File "/home/airflow/.local/lib/python3.7/site-packages/sqlalchemy/engine/default.py", line 584, in connect
    return self.dbapi.connect(*cargs, **cparams)
  File "/home/airflow/.local/lib/python3.7/site-packages/psycopg2/__init__.py", line 122, in connect
    conn = _connect(dsn, connection_factory=connection_factory, **kwasync)
sqlalchemy.exc.OperationalError: (psycopg2.OperationalError) connection to server at "postgres" (172.18.0.3), port 5432 failed: FATAL:  password authentication failed for user "airflow"

(Background on this error at: https://sqlalche.me/e/14/e3q8)
[2024-06-30T09:22:30.440+0000] {processor.py:652} WARNING - No viable dags retrieved from /opt/airflow/dags/P2M3_devi_nirfana_DAG.py
[2024-06-30T09:22:30.460+0000] {processor.py:161} INFO - Processing /opt/airflow/dags/P2M3_devi_nirfana_DAG.py took 0.457 seconds
[2024-06-30T09:22:33.032+0000] {processor.py:153} INFO - Started process (PID=249) to work on /opt/airflow/dags/P2M3_devi_nirfana_DAG.py
[2024-06-30T09:22:33.033+0000] {processor.py:640} INFO - Processing file /opt/airflow/dags/P2M3_devi_nirfana_DAG.py for tasks to queue
[2024-06-30T09:22:33.034+0000] {logging_mixin.py:115} INFO - [2024-06-30T09:22:33.034+0000] {dagbag.py:508} INFO - Filling up the DagBag from /opt/airflow/dags/P2M3_devi_nirfana_DAG.py
[2024-06-30T09:22:33.425+0000] {logging_mixin.py:115} INFO - [2024-06-30T09:22:33.420+0000] {dagbag.py:321} ERROR - Failed to import: /opt/airflow/dags/P2M3_devi_nirfana_DAG.py
Traceback (most recent call last):
  File "/home/airflow/.local/lib/python3.7/site-packages/sqlalchemy/engine/base.py", line 3243, in _wrap_pool_connect
    return fn()
  File "/home/airflow/.local/lib/python3.7/site-packages/sqlalchemy/pool/base.py", line 310, in connect
    return _ConnectionFairy._checkout(self)
  File "/home/airflow/.local/lib/python3.7/site-packages/sqlalchemy/pool/base.py", line 868, in _checkout
    fairy = _ConnectionRecord.checkout(pool)
  File "/home/airflow/.local/lib/python3.7/site-packages/sqlalchemy/pool/base.py", line 476, in checkout
    rec = pool._do_get()
  File "/home/airflow/.local/lib/python3.7/site-packages/sqlalchemy/pool/impl.py", line 146, in _do_get
    self._dec_overflow()
  File "/home/airflow/.local/lib/python3.7/site-packages/sqlalchemy/util/langhelpers.py", line 72, in __exit__
    with_traceback=exc_tb,
  File "/home/airflow/.local/lib/python3.7/site-packages/sqlalchemy/util/compat.py", line 207, in raise_
    raise exception
  File "/home/airflow/.local/lib/python3.7/site-packages/sqlalchemy/pool/impl.py", line 143, in _do_get
    return self._create_connection()
  File "/home/airflow/.local/lib/python3.7/site-packages/sqlalchemy/pool/base.py", line 256, in _create_connection
    return _ConnectionRecord(self)
  File "/home/airflow/.local/lib/python3.7/site-packages/sqlalchemy/pool/base.py", line 371, in __init__
    self.__connect()
  File "/home/airflow/.local/lib/python3.7/site-packages/sqlalchemy/pool/base.py", line 666, in __connect
    pool.logger.debug("Error on connect(): %s", e)
  File "/home/airflow/.local/lib/python3.7/site-packages/sqlalchemy/util/langhelpers.py", line 72, in __exit__
    with_traceback=exc_tb,
  File "/home/airflow/.local/lib/python3.7/site-packages/sqlalchemy/util/compat.py", line 207, in raise_
    raise exception
  File "/home/airflow/.local/lib/python3.7/site-packages/sqlalchemy/pool/base.py", line 661, in __connect
    self.dbapi_connection = connection = pool._invoke_creator(self)
  File "/home/airflow/.local/lib/python3.7/site-packages/sqlalchemy/engine/create.py", line 590, in connect
    return dialect.connect(*cargs, **cparams)
  File "/home/airflow/.local/lib/python3.7/site-packages/sqlalchemy/engine/default.py", line 584, in connect
    return self.dbapi.connect(*cargs, **cparams)
  File "/home/airflow/.local/lib/python3.7/site-packages/psycopg2/__init__.py", line 122, in connect
    conn = _connect(dsn, connection_factory=connection_factory, **kwasync)
psycopg2.OperationalError: connection to server at "postgres" (172.18.0.3), port 5432 failed: FATAL:  password authentication failed for user "airflow"


The above exception was the direct cause of the following exception:

Traceback (most recent call last):
  File "/home/airflow/.local/lib/python3.7/site-packages/airflow/models/dagbag.py", line 318, in parse
    loader.exec_module(new_module)
  File "<frozen importlib._bootstrap_external>", line 728, in exec_module
  File "<frozen importlib._bootstrap>", line 219, in _call_with_frames_removed
  File "/opt/airflow/dags/P2M3_devi_nirfana_DAG.py", line 28, in <module>
    conn = engine.connect()
  File "/home/airflow/.local/lib/python3.7/site-packages/sqlalchemy/engine/base.py", line 3197, in connect
    return self._connection_cls(self, close_with_result=close_with_result)
  File "/home/airflow/.local/lib/python3.7/site-packages/sqlalchemy/engine/base.py", line 96, in __init__
    else engine.raw_connection()
  File "/home/airflow/.local/lib/python3.7/site-packages/sqlalchemy/engine/base.py", line 3276, in raw_connection
    return self._wrap_pool_connect(self.pool.connect, _connection)
  File "/home/airflow/.local/lib/python3.7/site-packages/sqlalchemy/engine/base.py", line 3247, in _wrap_pool_connect
    e, dialect, self
  File "/home/airflow/.local/lib/python3.7/site-packages/sqlalchemy/engine/base.py", line 2101, in _handle_dbapi_exception_noconnection
    sqlalchemy_exception, with_traceback=exc_info[2], from_=e
  File "/home/airflow/.local/lib/python3.7/site-packages/sqlalchemy/util/compat.py", line 207, in raise_
    raise exception
  File "/home/airflow/.local/lib/python3.7/site-packages/sqlalchemy/engine/base.py", line 3243, in _wrap_pool_connect
    return fn()
  File "/home/airflow/.local/lib/python3.7/site-packages/sqlalchemy/pool/base.py", line 310, in connect
    return _ConnectionFairy._checkout(self)
  File "/home/airflow/.local/lib/python3.7/site-packages/sqlalchemy/pool/base.py", line 868, in _checkout
    fairy = _ConnectionRecord.checkout(pool)
  File "/home/airflow/.local/lib/python3.7/site-packages/sqlalchemy/pool/base.py", line 476, in checkout
    rec = pool._do_get()
  File "/home/airflow/.local/lib/python3.7/site-packages/sqlalchemy/pool/impl.py", line 146, in _do_get
    self._dec_overflow()
  File "/home/airflow/.local/lib/python3.7/site-packages/sqlalchemy/util/langhelpers.py", line 72, in __exit__
    with_traceback=exc_tb,
  File "/home/airflow/.local/lib/python3.7/site-packages/sqlalchemy/util/compat.py", line 207, in raise_
    raise exception
  File "/home/airflow/.local/lib/python3.7/site-packages/sqlalchemy/pool/impl.py", line 143, in _do_get
    return self._create_connection()
  File "/home/airflow/.local/lib/python3.7/site-packages/sqlalchemy/pool/base.py", line 256, in _create_connection
    return _ConnectionRecord(self)
  File "/home/airflow/.local/lib/python3.7/site-packages/sqlalchemy/pool/base.py", line 371, in __init__
    self.__connect()
  File "/home/airflow/.local/lib/python3.7/site-packages/sqlalchemy/pool/base.py", line 666, in __connect
    pool.logger.debug("Error on connect(): %s", e)
  File "/home/airflow/.local/lib/python3.7/site-packages/sqlalchemy/util/langhelpers.py", line 72, in __exit__
    with_traceback=exc_tb,
  File "/home/airflow/.local/lib/python3.7/site-packages/sqlalchemy/util/compat.py", line 207, in raise_
    raise exception
  File "/home/airflow/.local/lib/python3.7/site-packages/sqlalchemy/pool/base.py", line 661, in __connect
    self.dbapi_connection = connection = pool._invoke_creator(self)
  File "/home/airflow/.local/lib/python3.7/site-packages/sqlalchemy/engine/create.py", line 590, in connect
    return dialect.connect(*cargs, **cparams)
  File "/home/airflow/.local/lib/python3.7/site-packages/sqlalchemy/engine/default.py", line 584, in connect
    return self.dbapi.connect(*cargs, **cparams)
  File "/home/airflow/.local/lib/python3.7/site-packages/psycopg2/__init__.py", line 122, in connect
    conn = _connect(dsn, connection_factory=connection_factory, **kwasync)
sqlalchemy.exc.OperationalError: (psycopg2.OperationalError) connection to server at "postgres" (172.18.0.3), port 5432 failed: FATAL:  password authentication failed for user "airflow"

(Background on this error at: https://sqlalche.me/e/14/e3q8)
[2024-06-30T09:22:33.426+0000] {processor.py:652} WARNING - No viable dags retrieved from /opt/airflow/dags/P2M3_devi_nirfana_DAG.py
[2024-06-30T09:22:33.448+0000] {processor.py:161} INFO - Processing /opt/airflow/dags/P2M3_devi_nirfana_DAG.py took 0.422 seconds
[2024-06-30T09:23:01.198+0000] {processor.py:153} INFO - Started process (PID=255) to work on /opt/airflow/dags/P2M3_devi_nirfana_DAG.py
[2024-06-30T09:23:01.200+0000] {processor.py:640} INFO - Processing file /opt/airflow/dags/P2M3_devi_nirfana_DAG.py for tasks to queue
[2024-06-30T09:23:01.201+0000] {logging_mixin.py:115} INFO - [2024-06-30T09:23:01.201+0000] {dagbag.py:508} INFO - Filling up the DagBag from /opt/airflow/dags/P2M3_devi_nirfana_DAG.py
[2024-06-30T09:23:01.582+0000] {logging_mixin.py:115} INFO - [2024-06-30T09:23:01.578+0000] {dagbag.py:321} ERROR - Failed to import: /opt/airflow/dags/P2M3_devi_nirfana_DAG.py
Traceback (most recent call last):
  File "/home/airflow/.local/lib/python3.7/site-packages/sqlalchemy/engine/base.py", line 3243, in _wrap_pool_connect
    return fn()
  File "/home/airflow/.local/lib/python3.7/site-packages/sqlalchemy/pool/base.py", line 310, in connect
    return _ConnectionFairy._checkout(self)
  File "/home/airflow/.local/lib/python3.7/site-packages/sqlalchemy/pool/base.py", line 868, in _checkout
    fairy = _ConnectionRecord.checkout(pool)
  File "/home/airflow/.local/lib/python3.7/site-packages/sqlalchemy/pool/base.py", line 476, in checkout
    rec = pool._do_get()
  File "/home/airflow/.local/lib/python3.7/site-packages/sqlalchemy/pool/impl.py", line 146, in _do_get
    self._dec_overflow()
  File "/home/airflow/.local/lib/python3.7/site-packages/sqlalchemy/util/langhelpers.py", line 72, in __exit__
    with_traceback=exc_tb,
  File "/home/airflow/.local/lib/python3.7/site-packages/sqlalchemy/util/compat.py", line 207, in raise_
    raise exception
  File "/home/airflow/.local/lib/python3.7/site-packages/sqlalchemy/pool/impl.py", line 143, in _do_get
    return self._create_connection()
  File "/home/airflow/.local/lib/python3.7/site-packages/sqlalchemy/pool/base.py", line 256, in _create_connection
    return _ConnectionRecord(self)
  File "/home/airflow/.local/lib/python3.7/site-packages/sqlalchemy/pool/base.py", line 371, in __init__
    self.__connect()
  File "/home/airflow/.local/lib/python3.7/site-packages/sqlalchemy/pool/base.py", line 666, in __connect
    pool.logger.debug("Error on connect(): %s", e)
  File "/home/airflow/.local/lib/python3.7/site-packages/sqlalchemy/util/langhelpers.py", line 72, in __exit__
    with_traceback=exc_tb,
  File "/home/airflow/.local/lib/python3.7/site-packages/sqlalchemy/util/compat.py", line 207, in raise_
    raise exception
  File "/home/airflow/.local/lib/python3.7/site-packages/sqlalchemy/pool/base.py", line 661, in __connect
    self.dbapi_connection = connection = pool._invoke_creator(self)
  File "/home/airflow/.local/lib/python3.7/site-packages/sqlalchemy/engine/create.py", line 590, in connect
    return dialect.connect(*cargs, **cparams)
  File "/home/airflow/.local/lib/python3.7/site-packages/sqlalchemy/engine/default.py", line 584, in connect
    return self.dbapi.connect(*cargs, **cparams)
  File "/home/airflow/.local/lib/python3.7/site-packages/psycopg2/__init__.py", line 122, in connect
    conn = _connect(dsn, connection_factory=connection_factory, **kwasync)
psycopg2.OperationalError: connection to server at "postgres" (172.18.0.3), port 5432 failed: FATAL:  password authentication failed for user "airflow"


The above exception was the direct cause of the following exception:

Traceback (most recent call last):
  File "/home/airflow/.local/lib/python3.7/site-packages/airflow/models/dagbag.py", line 318, in parse
    loader.exec_module(new_module)
  File "<frozen importlib._bootstrap_external>", line 728, in exec_module
  File "<frozen importlib._bootstrap>", line 219, in _call_with_frames_removed
  File "/opt/airflow/dags/P2M3_devi_nirfana_DAG.py", line 28, in <module>
    conn = engine.connect()
  File "/home/airflow/.local/lib/python3.7/site-packages/sqlalchemy/engine/base.py", line 3197, in connect
    return self._connection_cls(self, close_with_result=close_with_result)
  File "/home/airflow/.local/lib/python3.7/site-packages/sqlalchemy/engine/base.py", line 96, in __init__
    else engine.raw_connection()
  File "/home/airflow/.local/lib/python3.7/site-packages/sqlalchemy/engine/base.py", line 3276, in raw_connection
    return self._wrap_pool_connect(self.pool.connect, _connection)
  File "/home/airflow/.local/lib/python3.7/site-packages/sqlalchemy/engine/base.py", line 3247, in _wrap_pool_connect
    e, dialect, self
  File "/home/airflow/.local/lib/python3.7/site-packages/sqlalchemy/engine/base.py", line 2101, in _handle_dbapi_exception_noconnection
    sqlalchemy_exception, with_traceback=exc_info[2], from_=e
  File "/home/airflow/.local/lib/python3.7/site-packages/sqlalchemy/util/compat.py", line 207, in raise_
    raise exception
  File "/home/airflow/.local/lib/python3.7/site-packages/sqlalchemy/engine/base.py", line 3243, in _wrap_pool_connect
    return fn()
  File "/home/airflow/.local/lib/python3.7/site-packages/sqlalchemy/pool/base.py", line 310, in connect
    return _ConnectionFairy._checkout(self)
  File "/home/airflow/.local/lib/python3.7/site-packages/sqlalchemy/pool/base.py", line 868, in _checkout
    fairy = _ConnectionRecord.checkout(pool)
  File "/home/airflow/.local/lib/python3.7/site-packages/sqlalchemy/pool/base.py", line 476, in checkout
    rec = pool._do_get()
  File "/home/airflow/.local/lib/python3.7/site-packages/sqlalchemy/pool/impl.py", line 146, in _do_get
    self._dec_overflow()
  File "/home/airflow/.local/lib/python3.7/site-packages/sqlalchemy/util/langhelpers.py", line 72, in __exit__
    with_traceback=exc_tb,
  File "/home/airflow/.local/lib/python3.7/site-packages/sqlalchemy/util/compat.py", line 207, in raise_
    raise exception
  File "/home/airflow/.local/lib/python3.7/site-packages/sqlalchemy/pool/impl.py", line 143, in _do_get
    return self._create_connection()
  File "/home/airflow/.local/lib/python3.7/site-packages/sqlalchemy/pool/base.py", line 256, in _create_connection
    return _ConnectionRecord(self)
  File "/home/airflow/.local/lib/python3.7/site-packages/sqlalchemy/pool/base.py", line 371, in __init__
    self.__connect()
  File "/home/airflow/.local/lib/python3.7/site-packages/sqlalchemy/pool/base.py", line 666, in __connect
    pool.logger.debug("Error on connect(): %s", e)
  File "/home/airflow/.local/lib/python3.7/site-packages/sqlalchemy/util/langhelpers.py", line 72, in __exit__
    with_traceback=exc_tb,
  File "/home/airflow/.local/lib/python3.7/site-packages/sqlalchemy/util/compat.py", line 207, in raise_
    raise exception
  File "/home/airflow/.local/lib/python3.7/site-packages/sqlalchemy/pool/base.py", line 661, in __connect
    self.dbapi_connection = connection = pool._invoke_creator(self)
  File "/home/airflow/.local/lib/python3.7/site-packages/sqlalchemy/engine/create.py", line 590, in connect
    return dialect.connect(*cargs, **cparams)
  File "/home/airflow/.local/lib/python3.7/site-packages/sqlalchemy/engine/default.py", line 584, in connect
    return self.dbapi.connect(*cargs, **cparams)
  File "/home/airflow/.local/lib/python3.7/site-packages/psycopg2/__init__.py", line 122, in connect
    conn = _connect(dsn, connection_factory=connection_factory, **kwasync)
sqlalchemy.exc.OperationalError: (psycopg2.OperationalError) connection to server at "postgres" (172.18.0.3), port 5432 failed: FATAL:  password authentication failed for user "airflow"

(Background on this error at: https://sqlalche.me/e/14/e3q8)
[2024-06-30T09:23:01.583+0000] {processor.py:652} WARNING - No viable dags retrieved from /opt/airflow/dags/P2M3_devi_nirfana_DAG.py
[2024-06-30T09:23:01.607+0000] {processor.py:161} INFO - Processing /opt/airflow/dags/P2M3_devi_nirfana_DAG.py took 0.413 seconds
[2024-06-30T09:23:11.621+0000] {processor.py:153} INFO - Started process (PID=261) to work on /opt/airflow/dags/P2M3_devi_nirfana_DAG.py
[2024-06-30T09:23:11.623+0000] {processor.py:640} INFO - Processing file /opt/airflow/dags/P2M3_devi_nirfana_DAG.py for tasks to queue
[2024-06-30T09:23:11.624+0000] {logging_mixin.py:115} INFO - [2024-06-30T09:23:11.624+0000] {dagbag.py:508} INFO - Filling up the DagBag from /opt/airflow/dags/P2M3_devi_nirfana_DAG.py
[2024-06-30T09:23:12.043+0000] {logging_mixin.py:115} INFO - [2024-06-30T09:23:12.039+0000] {dagbag.py:321} ERROR - Failed to import: /opt/airflow/dags/P2M3_devi_nirfana_DAG.py
Traceback (most recent call last):
  File "/home/airflow/.local/lib/python3.7/site-packages/sqlalchemy/engine/base.py", line 3243, in _wrap_pool_connect
    return fn()
  File "/home/airflow/.local/lib/python3.7/site-packages/sqlalchemy/pool/base.py", line 310, in connect
    return _ConnectionFairy._checkout(self)
  File "/home/airflow/.local/lib/python3.7/site-packages/sqlalchemy/pool/base.py", line 868, in _checkout
    fairy = _ConnectionRecord.checkout(pool)
  File "/home/airflow/.local/lib/python3.7/site-packages/sqlalchemy/pool/base.py", line 476, in checkout
    rec = pool._do_get()
  File "/home/airflow/.local/lib/python3.7/site-packages/sqlalchemy/pool/impl.py", line 146, in _do_get
    self._dec_overflow()
  File "/home/airflow/.local/lib/python3.7/site-packages/sqlalchemy/util/langhelpers.py", line 72, in __exit__
    with_traceback=exc_tb,
  File "/home/airflow/.local/lib/python3.7/site-packages/sqlalchemy/util/compat.py", line 207, in raise_
    raise exception
  File "/home/airflow/.local/lib/python3.7/site-packages/sqlalchemy/pool/impl.py", line 143, in _do_get
    return self._create_connection()
  File "/home/airflow/.local/lib/python3.7/site-packages/sqlalchemy/pool/base.py", line 256, in _create_connection
    return _ConnectionRecord(self)
  File "/home/airflow/.local/lib/python3.7/site-packages/sqlalchemy/pool/base.py", line 371, in __init__
    self.__connect()
  File "/home/airflow/.local/lib/python3.7/site-packages/sqlalchemy/pool/base.py", line 666, in __connect
    pool.logger.debug("Error on connect(): %s", e)
  File "/home/airflow/.local/lib/python3.7/site-packages/sqlalchemy/util/langhelpers.py", line 72, in __exit__
    with_traceback=exc_tb,
  File "/home/airflow/.local/lib/python3.7/site-packages/sqlalchemy/util/compat.py", line 207, in raise_
    raise exception
  File "/home/airflow/.local/lib/python3.7/site-packages/sqlalchemy/pool/base.py", line 661, in __connect
    self.dbapi_connection = connection = pool._invoke_creator(self)
  File "/home/airflow/.local/lib/python3.7/site-packages/sqlalchemy/engine/create.py", line 590, in connect
    return dialect.connect(*cargs, **cparams)
  File "/home/airflow/.local/lib/python3.7/site-packages/sqlalchemy/engine/default.py", line 584, in connect
    return self.dbapi.connect(*cargs, **cparams)
  File "/home/airflow/.local/lib/python3.7/site-packages/psycopg2/__init__.py", line 122, in connect
    conn = _connect(dsn, connection_factory=connection_factory, **kwasync)
psycopg2.OperationalError: connection to server at "postgres" (172.18.0.3), port 5432 failed: FATAL:  password authentication failed for user "airflow"


The above exception was the direct cause of the following exception:

Traceback (most recent call last):
  File "/home/airflow/.local/lib/python3.7/site-packages/airflow/models/dagbag.py", line 318, in parse
    loader.exec_module(new_module)
  File "<frozen importlib._bootstrap_external>", line 728, in exec_module
  File "<frozen importlib._bootstrap>", line 219, in _call_with_frames_removed
  File "/opt/airflow/dags/P2M3_devi_nirfana_DAG.py", line 28, in <module>
    conn = engine.connect()
  File "/home/airflow/.local/lib/python3.7/site-packages/sqlalchemy/engine/base.py", line 3197, in connect
    return self._connection_cls(self, close_with_result=close_with_result)
  File "/home/airflow/.local/lib/python3.7/site-packages/sqlalchemy/engine/base.py", line 96, in __init__
    else engine.raw_connection()
  File "/home/airflow/.local/lib/python3.7/site-packages/sqlalchemy/engine/base.py", line 3276, in raw_connection
    return self._wrap_pool_connect(self.pool.connect, _connection)
  File "/home/airflow/.local/lib/python3.7/site-packages/sqlalchemy/engine/base.py", line 3247, in _wrap_pool_connect
    e, dialect, self
  File "/home/airflow/.local/lib/python3.7/site-packages/sqlalchemy/engine/base.py", line 2101, in _handle_dbapi_exception_noconnection
    sqlalchemy_exception, with_traceback=exc_info[2], from_=e
  File "/home/airflow/.local/lib/python3.7/site-packages/sqlalchemy/util/compat.py", line 207, in raise_
    raise exception
  File "/home/airflow/.local/lib/python3.7/site-packages/sqlalchemy/engine/base.py", line 3243, in _wrap_pool_connect
    return fn()
  File "/home/airflow/.local/lib/python3.7/site-packages/sqlalchemy/pool/base.py", line 310, in connect
    return _ConnectionFairy._checkout(self)
  File "/home/airflow/.local/lib/python3.7/site-packages/sqlalchemy/pool/base.py", line 868, in _checkout
    fairy = _ConnectionRecord.checkout(pool)
  File "/home/airflow/.local/lib/python3.7/site-packages/sqlalchemy/pool/base.py", line 476, in checkout
    rec = pool._do_get()
  File "/home/airflow/.local/lib/python3.7/site-packages/sqlalchemy/pool/impl.py", line 146, in _do_get
    self._dec_overflow()
  File "/home/airflow/.local/lib/python3.7/site-packages/sqlalchemy/util/langhelpers.py", line 72, in __exit__
    with_traceback=exc_tb,
  File "/home/airflow/.local/lib/python3.7/site-packages/sqlalchemy/util/compat.py", line 207, in raise_
    raise exception
  File "/home/airflow/.local/lib/python3.7/site-packages/sqlalchemy/pool/impl.py", line 143, in _do_get
    return self._create_connection()
  File "/home/airflow/.local/lib/python3.7/site-packages/sqlalchemy/pool/base.py", line 256, in _create_connection
    return _ConnectionRecord(self)
  File "/home/airflow/.local/lib/python3.7/site-packages/sqlalchemy/pool/base.py", line 371, in __init__
    self.__connect()
  File "/home/airflow/.local/lib/python3.7/site-packages/sqlalchemy/pool/base.py", line 666, in __connect
    pool.logger.debug("Error on connect(): %s", e)
  File "/home/airflow/.local/lib/python3.7/site-packages/sqlalchemy/util/langhelpers.py", line 72, in __exit__
    with_traceback=exc_tb,
  File "/home/airflow/.local/lib/python3.7/site-packages/sqlalchemy/util/compat.py", line 207, in raise_
    raise exception
  File "/home/airflow/.local/lib/python3.7/site-packages/sqlalchemy/pool/base.py", line 661, in __connect
    self.dbapi_connection = connection = pool._invoke_creator(self)
  File "/home/airflow/.local/lib/python3.7/site-packages/sqlalchemy/engine/create.py", line 590, in connect
    return dialect.connect(*cargs, **cparams)
  File "/home/airflow/.local/lib/python3.7/site-packages/sqlalchemy/engine/default.py", line 584, in connect
    return self.dbapi.connect(*cargs, **cparams)
  File "/home/airflow/.local/lib/python3.7/site-packages/psycopg2/__init__.py", line 122, in connect
    conn = _connect(dsn, connection_factory=connection_factory, **kwasync)
sqlalchemy.exc.OperationalError: (psycopg2.OperationalError) connection to server at "postgres" (172.18.0.3), port 5432 failed: FATAL:  password authentication failed for user "airflow"

(Background on this error at: https://sqlalche.me/e/14/e3q8)
[2024-06-30T09:23:12.044+0000] {processor.py:652} WARNING - No viable dags retrieved from /opt/airflow/dags/P2M3_devi_nirfana_DAG.py
[2024-06-30T09:23:12.065+0000] {processor.py:161} INFO - Processing /opt/airflow/dags/P2M3_devi_nirfana_DAG.py took 0.448 seconds
[2024-06-30T09:23:17.116+0000] {processor.py:153} INFO - Started process (PID=267) to work on /opt/airflow/dags/P2M3_devi_nirfana_DAG.py
[2024-06-30T09:23:17.118+0000] {processor.py:640} INFO - Processing file /opt/airflow/dags/P2M3_devi_nirfana_DAG.py for tasks to queue
[2024-06-30T09:23:17.119+0000] {logging_mixin.py:115} INFO - [2024-06-30T09:23:17.119+0000] {dagbag.py:508} INFO - Filling up the DagBag from /opt/airflow/dags/P2M3_devi_nirfana_DAG.py
[2024-06-30T09:23:17.468+0000] {logging_mixin.py:115} INFO - [2024-06-30T09:23:17.465+0000] {dagbag.py:321} ERROR - Failed to import: /opt/airflow/dags/P2M3_devi_nirfana_DAG.py
Traceback (most recent call last):
  File "/home/airflow/.local/lib/python3.7/site-packages/sqlalchemy/engine/base.py", line 3243, in _wrap_pool_connect
    return fn()
  File "/home/airflow/.local/lib/python3.7/site-packages/sqlalchemy/pool/base.py", line 310, in connect
    return _ConnectionFairy._checkout(self)
  File "/home/airflow/.local/lib/python3.7/site-packages/sqlalchemy/pool/base.py", line 868, in _checkout
    fairy = _ConnectionRecord.checkout(pool)
  File "/home/airflow/.local/lib/python3.7/site-packages/sqlalchemy/pool/base.py", line 476, in checkout
    rec = pool._do_get()
  File "/home/airflow/.local/lib/python3.7/site-packages/sqlalchemy/pool/impl.py", line 146, in _do_get
    self._dec_overflow()
  File "/home/airflow/.local/lib/python3.7/site-packages/sqlalchemy/util/langhelpers.py", line 72, in __exit__
    with_traceback=exc_tb,
  File "/home/airflow/.local/lib/python3.7/site-packages/sqlalchemy/util/compat.py", line 207, in raise_
    raise exception
  File "/home/airflow/.local/lib/python3.7/site-packages/sqlalchemy/pool/impl.py", line 143, in _do_get
    return self._create_connection()
  File "/home/airflow/.local/lib/python3.7/site-packages/sqlalchemy/pool/base.py", line 256, in _create_connection
    return _ConnectionRecord(self)
  File "/home/airflow/.local/lib/python3.7/site-packages/sqlalchemy/pool/base.py", line 371, in __init__
    self.__connect()
  File "/home/airflow/.local/lib/python3.7/site-packages/sqlalchemy/pool/base.py", line 666, in __connect
    pool.logger.debug("Error on connect(): %s", e)
  File "/home/airflow/.local/lib/python3.7/site-packages/sqlalchemy/util/langhelpers.py", line 72, in __exit__
    with_traceback=exc_tb,
  File "/home/airflow/.local/lib/python3.7/site-packages/sqlalchemy/util/compat.py", line 207, in raise_
    raise exception
  File "/home/airflow/.local/lib/python3.7/site-packages/sqlalchemy/pool/base.py", line 661, in __connect
    self.dbapi_connection = connection = pool._invoke_creator(self)
  File "/home/airflow/.local/lib/python3.7/site-packages/sqlalchemy/engine/create.py", line 590, in connect
    return dialect.connect(*cargs, **cparams)
  File "/home/airflow/.local/lib/python3.7/site-packages/sqlalchemy/engine/default.py", line 584, in connect
    return self.dbapi.connect(*cargs, **cparams)
  File "/home/airflow/.local/lib/python3.7/site-packages/psycopg2/__init__.py", line 122, in connect
    conn = _connect(dsn, connection_factory=connection_factory, **kwasync)
psycopg2.OperationalError: connection to server at "postgres" (172.18.0.3), port 5432 failed: FATAL:  password authentication failed for user "airflow"


The above exception was the direct cause of the following exception:

Traceback (most recent call last):
  File "/home/airflow/.local/lib/python3.7/site-packages/airflow/models/dagbag.py", line 318, in parse
    loader.exec_module(new_module)
  File "<frozen importlib._bootstrap_external>", line 728, in exec_module
  File "<frozen importlib._bootstrap>", line 219, in _call_with_frames_removed
  File "/opt/airflow/dags/P2M3_devi_nirfana_DAG.py", line 28, in <module>
    conn = engine.connect()
  File "/home/airflow/.local/lib/python3.7/site-packages/sqlalchemy/engine/base.py", line 3197, in connect
    return self._connection_cls(self, close_with_result=close_with_result)
  File "/home/airflow/.local/lib/python3.7/site-packages/sqlalchemy/engine/base.py", line 96, in __init__
    else engine.raw_connection()
  File "/home/airflow/.local/lib/python3.7/site-packages/sqlalchemy/engine/base.py", line 3276, in raw_connection
    return self._wrap_pool_connect(self.pool.connect, _connection)
  File "/home/airflow/.local/lib/python3.7/site-packages/sqlalchemy/engine/base.py", line 3247, in _wrap_pool_connect
    e, dialect, self
  File "/home/airflow/.local/lib/python3.7/site-packages/sqlalchemy/engine/base.py", line 2101, in _handle_dbapi_exception_noconnection
    sqlalchemy_exception, with_traceback=exc_info[2], from_=e
  File "/home/airflow/.local/lib/python3.7/site-packages/sqlalchemy/util/compat.py", line 207, in raise_
    raise exception
  File "/home/airflow/.local/lib/python3.7/site-packages/sqlalchemy/engine/base.py", line 3243, in _wrap_pool_connect
    return fn()
  File "/home/airflow/.local/lib/python3.7/site-packages/sqlalchemy/pool/base.py", line 310, in connect
    return _ConnectionFairy._checkout(self)
  File "/home/airflow/.local/lib/python3.7/site-packages/sqlalchemy/pool/base.py", line 868, in _checkout
    fairy = _ConnectionRecord.checkout(pool)
  File "/home/airflow/.local/lib/python3.7/site-packages/sqlalchemy/pool/base.py", line 476, in checkout
    rec = pool._do_get()
  File "/home/airflow/.local/lib/python3.7/site-packages/sqlalchemy/pool/impl.py", line 146, in _do_get
    self._dec_overflow()
  File "/home/airflow/.local/lib/python3.7/site-packages/sqlalchemy/util/langhelpers.py", line 72, in __exit__
    with_traceback=exc_tb,
  File "/home/airflow/.local/lib/python3.7/site-packages/sqlalchemy/util/compat.py", line 207, in raise_
    raise exception
  File "/home/airflow/.local/lib/python3.7/site-packages/sqlalchemy/pool/impl.py", line 143, in _do_get
    return self._create_connection()
  File "/home/airflow/.local/lib/python3.7/site-packages/sqlalchemy/pool/base.py", line 256, in _create_connection
    return _ConnectionRecord(self)
  File "/home/airflow/.local/lib/python3.7/site-packages/sqlalchemy/pool/base.py", line 371, in __init__
    self.__connect()
  File "/home/airflow/.local/lib/python3.7/site-packages/sqlalchemy/pool/base.py", line 666, in __connect
    pool.logger.debug("Error on connect(): %s", e)
  File "/home/airflow/.local/lib/python3.7/site-packages/sqlalchemy/util/langhelpers.py", line 72, in __exit__
    with_traceback=exc_tb,
  File "/home/airflow/.local/lib/python3.7/site-packages/sqlalchemy/util/compat.py", line 207, in raise_
    raise exception
  File "/home/airflow/.local/lib/python3.7/site-packages/sqlalchemy/pool/base.py", line 661, in __connect
    self.dbapi_connection = connection = pool._invoke_creator(self)
  File "/home/airflow/.local/lib/python3.7/site-packages/sqlalchemy/engine/create.py", line 590, in connect
    return dialect.connect(*cargs, **cparams)
  File "/home/airflow/.local/lib/python3.7/site-packages/sqlalchemy/engine/default.py", line 584, in connect
    return self.dbapi.connect(*cargs, **cparams)
  File "/home/airflow/.local/lib/python3.7/site-packages/psycopg2/__init__.py", line 122, in connect
    conn = _connect(dsn, connection_factory=connection_factory, **kwasync)
sqlalchemy.exc.OperationalError: (psycopg2.OperationalError) connection to server at "postgres" (172.18.0.3), port 5432 failed: FATAL:  password authentication failed for user "airflow"

(Background on this error at: https://sqlalche.me/e/14/e3q8)
[2024-06-30T09:23:17.469+0000] {processor.py:652} WARNING - No viable dags retrieved from /opt/airflow/dags/P2M3_devi_nirfana_DAG.py
[2024-06-30T09:23:17.492+0000] {processor.py:161} INFO - Processing /opt/airflow/dags/P2M3_devi_nirfana_DAG.py took 0.380 seconds
[2024-06-30T09:23:19.136+0000] {processor.py:153} INFO - Started process (PID=273) to work on /opt/airflow/dags/P2M3_devi_nirfana_DAG.py
[2024-06-30T09:23:19.138+0000] {processor.py:640} INFO - Processing file /opt/airflow/dags/P2M3_devi_nirfana_DAG.py for tasks to queue
[2024-06-30T09:23:19.140+0000] {logging_mixin.py:115} INFO - [2024-06-30T09:23:19.139+0000] {dagbag.py:508} INFO - Filling up the DagBag from /opt/airflow/dags/P2M3_devi_nirfana_DAG.py
[2024-06-30T09:23:19.520+0000] {logging_mixin.py:115} INFO - [2024-06-30T09:23:19.516+0000] {dagbag.py:321} ERROR - Failed to import: /opt/airflow/dags/P2M3_devi_nirfana_DAG.py
Traceback (most recent call last):
  File "/home/airflow/.local/lib/python3.7/site-packages/sqlalchemy/engine/base.py", line 3243, in _wrap_pool_connect
    return fn()
  File "/home/airflow/.local/lib/python3.7/site-packages/sqlalchemy/pool/base.py", line 310, in connect
    return _ConnectionFairy._checkout(self)
  File "/home/airflow/.local/lib/python3.7/site-packages/sqlalchemy/pool/base.py", line 868, in _checkout
    fairy = _ConnectionRecord.checkout(pool)
  File "/home/airflow/.local/lib/python3.7/site-packages/sqlalchemy/pool/base.py", line 476, in checkout
    rec = pool._do_get()
  File "/home/airflow/.local/lib/python3.7/site-packages/sqlalchemy/pool/impl.py", line 146, in _do_get
    self._dec_overflow()
  File "/home/airflow/.local/lib/python3.7/site-packages/sqlalchemy/util/langhelpers.py", line 72, in __exit__
    with_traceback=exc_tb,
  File "/home/airflow/.local/lib/python3.7/site-packages/sqlalchemy/util/compat.py", line 207, in raise_
    raise exception
  File "/home/airflow/.local/lib/python3.7/site-packages/sqlalchemy/pool/impl.py", line 143, in _do_get
    return self._create_connection()
  File "/home/airflow/.local/lib/python3.7/site-packages/sqlalchemy/pool/base.py", line 256, in _create_connection
    return _ConnectionRecord(self)
  File "/home/airflow/.local/lib/python3.7/site-packages/sqlalchemy/pool/base.py", line 371, in __init__
    self.__connect()
  File "/home/airflow/.local/lib/python3.7/site-packages/sqlalchemy/pool/base.py", line 666, in __connect
    pool.logger.debug("Error on connect(): %s", e)
  File "/home/airflow/.local/lib/python3.7/site-packages/sqlalchemy/util/langhelpers.py", line 72, in __exit__
    with_traceback=exc_tb,
  File "/home/airflow/.local/lib/python3.7/site-packages/sqlalchemy/util/compat.py", line 207, in raise_
    raise exception
  File "/home/airflow/.local/lib/python3.7/site-packages/sqlalchemy/pool/base.py", line 661, in __connect
    self.dbapi_connection = connection = pool._invoke_creator(self)
  File "/home/airflow/.local/lib/python3.7/site-packages/sqlalchemy/engine/create.py", line 590, in connect
    return dialect.connect(*cargs, **cparams)
  File "/home/airflow/.local/lib/python3.7/site-packages/sqlalchemy/engine/default.py", line 584, in connect
    return self.dbapi.connect(*cargs, **cparams)
  File "/home/airflow/.local/lib/python3.7/site-packages/psycopg2/__init__.py", line 122, in connect
    conn = _connect(dsn, connection_factory=connection_factory, **kwasync)
psycopg2.OperationalError: connection to server at "postgres" (172.18.0.3), port 5432 failed: FATAL:  password authentication failed for user "airflow"


The above exception was the direct cause of the following exception:

Traceback (most recent call last):
  File "/home/airflow/.local/lib/python3.7/site-packages/airflow/models/dagbag.py", line 318, in parse
    loader.exec_module(new_module)
  File "<frozen importlib._bootstrap_external>", line 728, in exec_module
  File "<frozen importlib._bootstrap>", line 219, in _call_with_frames_removed
  File "/opt/airflow/dags/P2M3_devi_nirfana_DAG.py", line 28, in <module>
    conn = engine.connect()
  File "/home/airflow/.local/lib/python3.7/site-packages/sqlalchemy/engine/base.py", line 3197, in connect
    return self._connection_cls(self, close_with_result=close_with_result)
  File "/home/airflow/.local/lib/python3.7/site-packages/sqlalchemy/engine/base.py", line 96, in __init__
    else engine.raw_connection()
  File "/home/airflow/.local/lib/python3.7/site-packages/sqlalchemy/engine/base.py", line 3276, in raw_connection
    return self._wrap_pool_connect(self.pool.connect, _connection)
  File "/home/airflow/.local/lib/python3.7/site-packages/sqlalchemy/engine/base.py", line 3247, in _wrap_pool_connect
    e, dialect, self
  File "/home/airflow/.local/lib/python3.7/site-packages/sqlalchemy/engine/base.py", line 2101, in _handle_dbapi_exception_noconnection
    sqlalchemy_exception, with_traceback=exc_info[2], from_=e
  File "/home/airflow/.local/lib/python3.7/site-packages/sqlalchemy/util/compat.py", line 207, in raise_
    raise exception
  File "/home/airflow/.local/lib/python3.7/site-packages/sqlalchemy/engine/base.py", line 3243, in _wrap_pool_connect
    return fn()
  File "/home/airflow/.local/lib/python3.7/site-packages/sqlalchemy/pool/base.py", line 310, in connect
    return _ConnectionFairy._checkout(self)
  File "/home/airflow/.local/lib/python3.7/site-packages/sqlalchemy/pool/base.py", line 868, in _checkout
    fairy = _ConnectionRecord.checkout(pool)
  File "/home/airflow/.local/lib/python3.7/site-packages/sqlalchemy/pool/base.py", line 476, in checkout
    rec = pool._do_get()
  File "/home/airflow/.local/lib/python3.7/site-packages/sqlalchemy/pool/impl.py", line 146, in _do_get
    self._dec_overflow()
  File "/home/airflow/.local/lib/python3.7/site-packages/sqlalchemy/util/langhelpers.py", line 72, in __exit__
    with_traceback=exc_tb,
  File "/home/airflow/.local/lib/python3.7/site-packages/sqlalchemy/util/compat.py", line 207, in raise_
    raise exception
  File "/home/airflow/.local/lib/python3.7/site-packages/sqlalchemy/pool/impl.py", line 143, in _do_get
    return self._create_connection()
  File "/home/airflow/.local/lib/python3.7/site-packages/sqlalchemy/pool/base.py", line 256, in _create_connection
    return _ConnectionRecord(self)
  File "/home/airflow/.local/lib/python3.7/site-packages/sqlalchemy/pool/base.py", line 371, in __init__
    self.__connect()
  File "/home/airflow/.local/lib/python3.7/site-packages/sqlalchemy/pool/base.py", line 666, in __connect
    pool.logger.debug("Error on connect(): %s", e)
  File "/home/airflow/.local/lib/python3.7/site-packages/sqlalchemy/util/langhelpers.py", line 72, in __exit__
    with_traceback=exc_tb,
  File "/home/airflow/.local/lib/python3.7/site-packages/sqlalchemy/util/compat.py", line 207, in raise_
    raise exception
  File "/home/airflow/.local/lib/python3.7/site-packages/sqlalchemy/pool/base.py", line 661, in __connect
    self.dbapi_connection = connection = pool._invoke_creator(self)
  File "/home/airflow/.local/lib/python3.7/site-packages/sqlalchemy/engine/create.py", line 590, in connect
    return dialect.connect(*cargs, **cparams)
  File "/home/airflow/.local/lib/python3.7/site-packages/sqlalchemy/engine/default.py", line 584, in connect
    return self.dbapi.connect(*cargs, **cparams)
  File "/home/airflow/.local/lib/python3.7/site-packages/psycopg2/__init__.py", line 122, in connect
    conn = _connect(dsn, connection_factory=connection_factory, **kwasync)
sqlalchemy.exc.OperationalError: (psycopg2.OperationalError) connection to server at "postgres" (172.18.0.3), port 5432 failed: FATAL:  password authentication failed for user "airflow"

(Background on this error at: https://sqlalche.me/e/14/e3q8)
[2024-06-30T09:23:19.522+0000] {processor.py:652} WARNING - No viable dags retrieved from /opt/airflow/dags/P2M3_devi_nirfana_DAG.py
[2024-06-30T09:23:19.544+0000] {processor.py:161} INFO - Processing /opt/airflow/dags/P2M3_devi_nirfana_DAG.py took 0.414 seconds
[2024-06-30T09:23:31.578+0000] {processor.py:153} INFO - Started process (PID=279) to work on /opt/airflow/dags/P2M3_devi_nirfana_DAG.py
[2024-06-30T09:23:31.579+0000] {processor.py:640} INFO - Processing file /opt/airflow/dags/P2M3_devi_nirfana_DAG.py for tasks to queue
[2024-06-30T09:23:31.580+0000] {logging_mixin.py:115} INFO - [2024-06-30T09:23:31.580+0000] {dagbag.py:508} INFO - Filling up the DagBag from /opt/airflow/dags/P2M3_devi_nirfana_DAG.py
[2024-06-30T09:23:31.971+0000] {logging_mixin.py:115} INFO - [2024-06-30T09:23:31.966+0000] {dagbag.py:321} ERROR - Failed to import: /opt/airflow/dags/P2M3_devi_nirfana_DAG.py
Traceback (most recent call last):
  File "/home/airflow/.local/lib/python3.7/site-packages/sqlalchemy/engine/base.py", line 3243, in _wrap_pool_connect
    return fn()
  File "/home/airflow/.local/lib/python3.7/site-packages/sqlalchemy/pool/base.py", line 310, in connect
    return _ConnectionFairy._checkout(self)
  File "/home/airflow/.local/lib/python3.7/site-packages/sqlalchemy/pool/base.py", line 868, in _checkout
    fairy = _ConnectionRecord.checkout(pool)
  File "/home/airflow/.local/lib/python3.7/site-packages/sqlalchemy/pool/base.py", line 476, in checkout
    rec = pool._do_get()
  File "/home/airflow/.local/lib/python3.7/site-packages/sqlalchemy/pool/impl.py", line 146, in _do_get
    self._dec_overflow()
  File "/home/airflow/.local/lib/python3.7/site-packages/sqlalchemy/util/langhelpers.py", line 72, in __exit__
    with_traceback=exc_tb,
  File "/home/airflow/.local/lib/python3.7/site-packages/sqlalchemy/util/compat.py", line 207, in raise_
    raise exception
  File "/home/airflow/.local/lib/python3.7/site-packages/sqlalchemy/pool/impl.py", line 143, in _do_get
    return self._create_connection()
  File "/home/airflow/.local/lib/python3.7/site-packages/sqlalchemy/pool/base.py", line 256, in _create_connection
    return _ConnectionRecord(self)
  File "/home/airflow/.local/lib/python3.7/site-packages/sqlalchemy/pool/base.py", line 371, in __init__
    self.__connect()
  File "/home/airflow/.local/lib/python3.7/site-packages/sqlalchemy/pool/base.py", line 666, in __connect
    pool.logger.debug("Error on connect(): %s", e)
  File "/home/airflow/.local/lib/python3.7/site-packages/sqlalchemy/util/langhelpers.py", line 72, in __exit__
    with_traceback=exc_tb,
  File "/home/airflow/.local/lib/python3.7/site-packages/sqlalchemy/util/compat.py", line 207, in raise_
    raise exception
  File "/home/airflow/.local/lib/python3.7/site-packages/sqlalchemy/pool/base.py", line 661, in __connect
    self.dbapi_connection = connection = pool._invoke_creator(self)
  File "/home/airflow/.local/lib/python3.7/site-packages/sqlalchemy/engine/create.py", line 590, in connect
    return dialect.connect(*cargs, **cparams)
  File "/home/airflow/.local/lib/python3.7/site-packages/sqlalchemy/engine/default.py", line 584, in connect
    return self.dbapi.connect(*cargs, **cparams)
  File "/home/airflow/.local/lib/python3.7/site-packages/psycopg2/__init__.py", line 122, in connect
    conn = _connect(dsn, connection_factory=connection_factory, **kwasync)
psycopg2.OperationalError: connection to server at "postgres" (172.18.0.3), port 5432 failed: FATAL:  password authentication failed for user "airflow"


The above exception was the direct cause of the following exception:

Traceback (most recent call last):
  File "/home/airflow/.local/lib/python3.7/site-packages/airflow/models/dagbag.py", line 318, in parse
    loader.exec_module(new_module)
  File "<frozen importlib._bootstrap_external>", line 728, in exec_module
  File "<frozen importlib._bootstrap>", line 219, in _call_with_frames_removed
  File "/opt/airflow/dags/P2M3_devi_nirfana_DAG.py", line 28, in <module>
    conn = engine.connect()
  File "/home/airflow/.local/lib/python3.7/site-packages/sqlalchemy/engine/base.py", line 3197, in connect
    return self._connection_cls(self, close_with_result=close_with_result)
  File "/home/airflow/.local/lib/python3.7/site-packages/sqlalchemy/engine/base.py", line 96, in __init__
    else engine.raw_connection()
  File "/home/airflow/.local/lib/python3.7/site-packages/sqlalchemy/engine/base.py", line 3276, in raw_connection
    return self._wrap_pool_connect(self.pool.connect, _connection)
  File "/home/airflow/.local/lib/python3.7/site-packages/sqlalchemy/engine/base.py", line 3247, in _wrap_pool_connect
    e, dialect, self
  File "/home/airflow/.local/lib/python3.7/site-packages/sqlalchemy/engine/base.py", line 2101, in _handle_dbapi_exception_noconnection
    sqlalchemy_exception, with_traceback=exc_info[2], from_=e
  File "/home/airflow/.local/lib/python3.7/site-packages/sqlalchemy/util/compat.py", line 207, in raise_
    raise exception
  File "/home/airflow/.local/lib/python3.7/site-packages/sqlalchemy/engine/base.py", line 3243, in _wrap_pool_connect
    return fn()
  File "/home/airflow/.local/lib/python3.7/site-packages/sqlalchemy/pool/base.py", line 310, in connect
    return _ConnectionFairy._checkout(self)
  File "/home/airflow/.local/lib/python3.7/site-packages/sqlalchemy/pool/base.py", line 868, in _checkout
    fairy = _ConnectionRecord.checkout(pool)
  File "/home/airflow/.local/lib/python3.7/site-packages/sqlalchemy/pool/base.py", line 476, in checkout
    rec = pool._do_get()
  File "/home/airflow/.local/lib/python3.7/site-packages/sqlalchemy/pool/impl.py", line 146, in _do_get
    self._dec_overflow()
  File "/home/airflow/.local/lib/python3.7/site-packages/sqlalchemy/util/langhelpers.py", line 72, in __exit__
    with_traceback=exc_tb,
  File "/home/airflow/.local/lib/python3.7/site-packages/sqlalchemy/util/compat.py", line 207, in raise_
    raise exception
  File "/home/airflow/.local/lib/python3.7/site-packages/sqlalchemy/pool/impl.py", line 143, in _do_get
    return self._create_connection()
  File "/home/airflow/.local/lib/python3.7/site-packages/sqlalchemy/pool/base.py", line 256, in _create_connection
    return _ConnectionRecord(self)
  File "/home/airflow/.local/lib/python3.7/site-packages/sqlalchemy/pool/base.py", line 371, in __init__
    self.__connect()
  File "/home/airflow/.local/lib/python3.7/site-packages/sqlalchemy/pool/base.py", line 666, in __connect
    pool.logger.debug("Error on connect(): %s", e)
  File "/home/airflow/.local/lib/python3.7/site-packages/sqlalchemy/util/langhelpers.py", line 72, in __exit__
    with_traceback=exc_tb,
  File "/home/airflow/.local/lib/python3.7/site-packages/sqlalchemy/util/compat.py", line 207, in raise_
    raise exception
  File "/home/airflow/.local/lib/python3.7/site-packages/sqlalchemy/pool/base.py", line 661, in __connect
    self.dbapi_connection = connection = pool._invoke_creator(self)
  File "/home/airflow/.local/lib/python3.7/site-packages/sqlalchemy/engine/create.py", line 590, in connect
    return dialect.connect(*cargs, **cparams)
  File "/home/airflow/.local/lib/python3.7/site-packages/sqlalchemy/engine/default.py", line 584, in connect
    return self.dbapi.connect(*cargs, **cparams)
  File "/home/airflow/.local/lib/python3.7/site-packages/psycopg2/__init__.py", line 122, in connect
    conn = _connect(dsn, connection_factory=connection_factory, **kwasync)
sqlalchemy.exc.OperationalError: (psycopg2.OperationalError) connection to server at "postgres" (172.18.0.3), port 5432 failed: FATAL:  password authentication failed for user "airflow"

(Background on this error at: https://sqlalche.me/e/14/e3q8)
[2024-06-30T09:23:31.972+0000] {processor.py:652} WARNING - No viable dags retrieved from /opt/airflow/dags/P2M3_devi_nirfana_DAG.py
[2024-06-30T09:23:31.995+0000] {processor.py:161} INFO - Processing /opt/airflow/dags/P2M3_devi_nirfana_DAG.py took 0.421 seconds
[2024-06-30T09:23:36.625+0000] {processor.py:153} INFO - Started process (PID=285) to work on /opt/airflow/dags/P2M3_devi_nirfana_DAG.py
[2024-06-30T09:23:36.626+0000] {processor.py:640} INFO - Processing file /opt/airflow/dags/P2M3_devi_nirfana_DAG.py for tasks to queue
[2024-06-30T09:23:36.627+0000] {logging_mixin.py:115} INFO - [2024-06-30T09:23:36.627+0000] {dagbag.py:508} INFO - Filling up the DagBag from /opt/airflow/dags/P2M3_devi_nirfana_DAG.py
[2024-06-30T09:23:37.020+0000] {logging_mixin.py:115} INFO - [2024-06-30T09:23:37.016+0000] {dagbag.py:321} ERROR - Failed to import: /opt/airflow/dags/P2M3_devi_nirfana_DAG.py
Traceback (most recent call last):
  File "/home/airflow/.local/lib/python3.7/site-packages/sqlalchemy/engine/base.py", line 3243, in _wrap_pool_connect
    return fn()
  File "/home/airflow/.local/lib/python3.7/site-packages/sqlalchemy/pool/base.py", line 310, in connect
    return _ConnectionFairy._checkout(self)
  File "/home/airflow/.local/lib/python3.7/site-packages/sqlalchemy/pool/base.py", line 868, in _checkout
    fairy = _ConnectionRecord.checkout(pool)
  File "/home/airflow/.local/lib/python3.7/site-packages/sqlalchemy/pool/base.py", line 476, in checkout
    rec = pool._do_get()
  File "/home/airflow/.local/lib/python3.7/site-packages/sqlalchemy/pool/impl.py", line 146, in _do_get
    self._dec_overflow()
  File "/home/airflow/.local/lib/python3.7/site-packages/sqlalchemy/util/langhelpers.py", line 72, in __exit__
    with_traceback=exc_tb,
  File "/home/airflow/.local/lib/python3.7/site-packages/sqlalchemy/util/compat.py", line 207, in raise_
    raise exception
  File "/home/airflow/.local/lib/python3.7/site-packages/sqlalchemy/pool/impl.py", line 143, in _do_get
    return self._create_connection()
  File "/home/airflow/.local/lib/python3.7/site-packages/sqlalchemy/pool/base.py", line 256, in _create_connection
    return _ConnectionRecord(self)
  File "/home/airflow/.local/lib/python3.7/site-packages/sqlalchemy/pool/base.py", line 371, in __init__
    self.__connect()
  File "/home/airflow/.local/lib/python3.7/site-packages/sqlalchemy/pool/base.py", line 666, in __connect
    pool.logger.debug("Error on connect(): %s", e)
  File "/home/airflow/.local/lib/python3.7/site-packages/sqlalchemy/util/langhelpers.py", line 72, in __exit__
    with_traceback=exc_tb,
  File "/home/airflow/.local/lib/python3.7/site-packages/sqlalchemy/util/compat.py", line 207, in raise_
    raise exception
  File "/home/airflow/.local/lib/python3.7/site-packages/sqlalchemy/pool/base.py", line 661, in __connect
    self.dbapi_connection = connection = pool._invoke_creator(self)
  File "/home/airflow/.local/lib/python3.7/site-packages/sqlalchemy/engine/create.py", line 590, in connect
    return dialect.connect(*cargs, **cparams)
  File "/home/airflow/.local/lib/python3.7/site-packages/sqlalchemy/engine/default.py", line 584, in connect
    return self.dbapi.connect(*cargs, **cparams)
  File "/home/airflow/.local/lib/python3.7/site-packages/psycopg2/__init__.py", line 122, in connect
    conn = _connect(dsn, connection_factory=connection_factory, **kwasync)
psycopg2.OperationalError: connection to server at "postgres" (172.18.0.3), port 5432 failed: FATAL:  password authentication failed for user "airflow"


The above exception was the direct cause of the following exception:

Traceback (most recent call last):
  File "/home/airflow/.local/lib/python3.7/site-packages/airflow/models/dagbag.py", line 318, in parse
    loader.exec_module(new_module)
  File "<frozen importlib._bootstrap_external>", line 728, in exec_module
  File "<frozen importlib._bootstrap>", line 219, in _call_with_frames_removed
  File "/opt/airflow/dags/P2M3_devi_nirfana_DAG.py", line 28, in <module>
    conn = engine.connect()
  File "/home/airflow/.local/lib/python3.7/site-packages/sqlalchemy/engine/base.py", line 3197, in connect
    return self._connection_cls(self, close_with_result=close_with_result)
  File "/home/airflow/.local/lib/python3.7/site-packages/sqlalchemy/engine/base.py", line 96, in __init__
    else engine.raw_connection()
  File "/home/airflow/.local/lib/python3.7/site-packages/sqlalchemy/engine/base.py", line 3276, in raw_connection
    return self._wrap_pool_connect(self.pool.connect, _connection)
  File "/home/airflow/.local/lib/python3.7/site-packages/sqlalchemy/engine/base.py", line 3247, in _wrap_pool_connect
    e, dialect, self
  File "/home/airflow/.local/lib/python3.7/site-packages/sqlalchemy/engine/base.py", line 2101, in _handle_dbapi_exception_noconnection
    sqlalchemy_exception, with_traceback=exc_info[2], from_=e
  File "/home/airflow/.local/lib/python3.7/site-packages/sqlalchemy/util/compat.py", line 207, in raise_
    raise exception
  File "/home/airflow/.local/lib/python3.7/site-packages/sqlalchemy/engine/base.py", line 3243, in _wrap_pool_connect
    return fn()
  File "/home/airflow/.local/lib/python3.7/site-packages/sqlalchemy/pool/base.py", line 310, in connect
    return _ConnectionFairy._checkout(self)
  File "/home/airflow/.local/lib/python3.7/site-packages/sqlalchemy/pool/base.py", line 868, in _checkout
    fairy = _ConnectionRecord.checkout(pool)
  File "/home/airflow/.local/lib/python3.7/site-packages/sqlalchemy/pool/base.py", line 476, in checkout
    rec = pool._do_get()
  File "/home/airflow/.local/lib/python3.7/site-packages/sqlalchemy/pool/impl.py", line 146, in _do_get
    self._dec_overflow()
  File "/home/airflow/.local/lib/python3.7/site-packages/sqlalchemy/util/langhelpers.py", line 72, in __exit__
    with_traceback=exc_tb,
  File "/home/airflow/.local/lib/python3.7/site-packages/sqlalchemy/util/compat.py", line 207, in raise_
    raise exception
  File "/home/airflow/.local/lib/python3.7/site-packages/sqlalchemy/pool/impl.py", line 143, in _do_get
    return self._create_connection()
  File "/home/airflow/.local/lib/python3.7/site-packages/sqlalchemy/pool/base.py", line 256, in _create_connection
    return _ConnectionRecord(self)
  File "/home/airflow/.local/lib/python3.7/site-packages/sqlalchemy/pool/base.py", line 371, in __init__
    self.__connect()
  File "/home/airflow/.local/lib/python3.7/site-packages/sqlalchemy/pool/base.py", line 666, in __connect
    pool.logger.debug("Error on connect(): %s", e)
  File "/home/airflow/.local/lib/python3.7/site-packages/sqlalchemy/util/langhelpers.py", line 72, in __exit__
    with_traceback=exc_tb,
  File "/home/airflow/.local/lib/python3.7/site-packages/sqlalchemy/util/compat.py", line 207, in raise_
    raise exception
  File "/home/airflow/.local/lib/python3.7/site-packages/sqlalchemy/pool/base.py", line 661, in __connect
    self.dbapi_connection = connection = pool._invoke_creator(self)
  File "/home/airflow/.local/lib/python3.7/site-packages/sqlalchemy/engine/create.py", line 590, in connect
    return dialect.connect(*cargs, **cparams)
  File "/home/airflow/.local/lib/python3.7/site-packages/sqlalchemy/engine/default.py", line 584, in connect
    return self.dbapi.connect(*cargs, **cparams)
  File "/home/airflow/.local/lib/python3.7/site-packages/psycopg2/__init__.py", line 122, in connect
    conn = _connect(dsn, connection_factory=connection_factory, **kwasync)
sqlalchemy.exc.OperationalError: (psycopg2.OperationalError) connection to server at "postgres" (172.18.0.3), port 5432 failed: FATAL:  password authentication failed for user "airflow"

(Background on this error at: https://sqlalche.me/e/14/e3q8)
[2024-06-30T09:23:37.021+0000] {processor.py:652} WARNING - No viable dags retrieved from /opt/airflow/dags/P2M3_devi_nirfana_DAG.py
[2024-06-30T09:23:37.041+0000] {processor.py:161} INFO - Processing /opt/airflow/dags/P2M3_devi_nirfana_DAG.py took 0.420 seconds
[2024-06-30T09:23:42.102+0000] {processor.py:153} INFO - Started process (PID=291) to work on /opt/airflow/dags/P2M3_devi_nirfana_DAG.py
[2024-06-30T09:23:42.104+0000] {processor.py:640} INFO - Processing file /opt/airflow/dags/P2M3_devi_nirfana_DAG.py for tasks to queue
[2024-06-30T09:23:42.105+0000] {logging_mixin.py:115} INFO - [2024-06-30T09:23:42.105+0000] {dagbag.py:508} INFO - Filling up the DagBag from /opt/airflow/dags/P2M3_devi_nirfana_DAG.py
[2024-06-30T09:23:42.531+0000] {logging_mixin.py:115} INFO - [2024-06-30T09:23:42.527+0000] {dagbag.py:321} ERROR - Failed to import: /opt/airflow/dags/P2M3_devi_nirfana_DAG.py
Traceback (most recent call last):
  File "/home/airflow/.local/lib/python3.7/site-packages/sqlalchemy/engine/base.py", line 3243, in _wrap_pool_connect
    return fn()
  File "/home/airflow/.local/lib/python3.7/site-packages/sqlalchemy/pool/base.py", line 310, in connect
    return _ConnectionFairy._checkout(self)
  File "/home/airflow/.local/lib/python3.7/site-packages/sqlalchemy/pool/base.py", line 868, in _checkout
    fairy = _ConnectionRecord.checkout(pool)
  File "/home/airflow/.local/lib/python3.7/site-packages/sqlalchemy/pool/base.py", line 476, in checkout
    rec = pool._do_get()
  File "/home/airflow/.local/lib/python3.7/site-packages/sqlalchemy/pool/impl.py", line 146, in _do_get
    self._dec_overflow()
  File "/home/airflow/.local/lib/python3.7/site-packages/sqlalchemy/util/langhelpers.py", line 72, in __exit__
    with_traceback=exc_tb,
  File "/home/airflow/.local/lib/python3.7/site-packages/sqlalchemy/util/compat.py", line 207, in raise_
    raise exception
  File "/home/airflow/.local/lib/python3.7/site-packages/sqlalchemy/pool/impl.py", line 143, in _do_get
    return self._create_connection()
  File "/home/airflow/.local/lib/python3.7/site-packages/sqlalchemy/pool/base.py", line 256, in _create_connection
    return _ConnectionRecord(self)
  File "/home/airflow/.local/lib/python3.7/site-packages/sqlalchemy/pool/base.py", line 371, in __init__
    self.__connect()
  File "/home/airflow/.local/lib/python3.7/site-packages/sqlalchemy/pool/base.py", line 666, in __connect
    pool.logger.debug("Error on connect(): %s", e)
  File "/home/airflow/.local/lib/python3.7/site-packages/sqlalchemy/util/langhelpers.py", line 72, in __exit__
    with_traceback=exc_tb,
  File "/home/airflow/.local/lib/python3.7/site-packages/sqlalchemy/util/compat.py", line 207, in raise_
    raise exception
  File "/home/airflow/.local/lib/python3.7/site-packages/sqlalchemy/pool/base.py", line 661, in __connect
    self.dbapi_connection = connection = pool._invoke_creator(self)
  File "/home/airflow/.local/lib/python3.7/site-packages/sqlalchemy/engine/create.py", line 590, in connect
    return dialect.connect(*cargs, **cparams)
  File "/home/airflow/.local/lib/python3.7/site-packages/sqlalchemy/engine/default.py", line 584, in connect
    return self.dbapi.connect(*cargs, **cparams)
  File "/home/airflow/.local/lib/python3.7/site-packages/psycopg2/__init__.py", line 122, in connect
    conn = _connect(dsn, connection_factory=connection_factory, **kwasync)
psycopg2.OperationalError: connection to server at "postgres" (172.18.0.3), port 5432 failed: FATAL:  password authentication failed for user "airflow"


The above exception was the direct cause of the following exception:

Traceback (most recent call last):
  File "/home/airflow/.local/lib/python3.7/site-packages/airflow/models/dagbag.py", line 318, in parse
    loader.exec_module(new_module)
  File "<frozen importlib._bootstrap_external>", line 728, in exec_module
  File "<frozen importlib._bootstrap>", line 219, in _call_with_frames_removed
  File "/opt/airflow/dags/P2M3_devi_nirfana_DAG.py", line 28, in <module>
    conn = engine.connect()
  File "/home/airflow/.local/lib/python3.7/site-packages/sqlalchemy/engine/base.py", line 3197, in connect
    return self._connection_cls(self, close_with_result=close_with_result)
  File "/home/airflow/.local/lib/python3.7/site-packages/sqlalchemy/engine/base.py", line 96, in __init__
    else engine.raw_connection()
  File "/home/airflow/.local/lib/python3.7/site-packages/sqlalchemy/engine/base.py", line 3276, in raw_connection
    return self._wrap_pool_connect(self.pool.connect, _connection)
  File "/home/airflow/.local/lib/python3.7/site-packages/sqlalchemy/engine/base.py", line 3247, in _wrap_pool_connect
    e, dialect, self
  File "/home/airflow/.local/lib/python3.7/site-packages/sqlalchemy/engine/base.py", line 2101, in _handle_dbapi_exception_noconnection
    sqlalchemy_exception, with_traceback=exc_info[2], from_=e
  File "/home/airflow/.local/lib/python3.7/site-packages/sqlalchemy/util/compat.py", line 207, in raise_
    raise exception
  File "/home/airflow/.local/lib/python3.7/site-packages/sqlalchemy/engine/base.py", line 3243, in _wrap_pool_connect
    return fn()
  File "/home/airflow/.local/lib/python3.7/site-packages/sqlalchemy/pool/base.py", line 310, in connect
    return _ConnectionFairy._checkout(self)
  File "/home/airflow/.local/lib/python3.7/site-packages/sqlalchemy/pool/base.py", line 868, in _checkout
    fairy = _ConnectionRecord.checkout(pool)
  File "/home/airflow/.local/lib/python3.7/site-packages/sqlalchemy/pool/base.py", line 476, in checkout
    rec = pool._do_get()
  File "/home/airflow/.local/lib/python3.7/site-packages/sqlalchemy/pool/impl.py", line 146, in _do_get
    self._dec_overflow()
  File "/home/airflow/.local/lib/python3.7/site-packages/sqlalchemy/util/langhelpers.py", line 72, in __exit__
    with_traceback=exc_tb,
  File "/home/airflow/.local/lib/python3.7/site-packages/sqlalchemy/util/compat.py", line 207, in raise_
    raise exception
  File "/home/airflow/.local/lib/python3.7/site-packages/sqlalchemy/pool/impl.py", line 143, in _do_get
    return self._create_connection()
  File "/home/airflow/.local/lib/python3.7/site-packages/sqlalchemy/pool/base.py", line 256, in _create_connection
    return _ConnectionRecord(self)
  File "/home/airflow/.local/lib/python3.7/site-packages/sqlalchemy/pool/base.py", line 371, in __init__
    self.__connect()
  File "/home/airflow/.local/lib/python3.7/site-packages/sqlalchemy/pool/base.py", line 666, in __connect
    pool.logger.debug("Error on connect(): %s", e)
  File "/home/airflow/.local/lib/python3.7/site-packages/sqlalchemy/util/langhelpers.py", line 72, in __exit__
    with_traceback=exc_tb,
  File "/home/airflow/.local/lib/python3.7/site-packages/sqlalchemy/util/compat.py", line 207, in raise_
    raise exception
  File "/home/airflow/.local/lib/python3.7/site-packages/sqlalchemy/pool/base.py", line 661, in __connect
    self.dbapi_connection = connection = pool._invoke_creator(self)
  File "/home/airflow/.local/lib/python3.7/site-packages/sqlalchemy/engine/create.py", line 590, in connect
    return dialect.connect(*cargs, **cparams)
  File "/home/airflow/.local/lib/python3.7/site-packages/sqlalchemy/engine/default.py", line 584, in connect
    return self.dbapi.connect(*cargs, **cparams)
  File "/home/airflow/.local/lib/python3.7/site-packages/psycopg2/__init__.py", line 122, in connect
    conn = _connect(dsn, connection_factory=connection_factory, **kwasync)
sqlalchemy.exc.OperationalError: (psycopg2.OperationalError) connection to server at "postgres" (172.18.0.3), port 5432 failed: FATAL:  password authentication failed for user "airflow"

(Background on this error at: https://sqlalche.me/e/14/e3q8)
[2024-06-30T09:23:42.532+0000] {processor.py:652} WARNING - No viable dags retrieved from /opt/airflow/dags/P2M3_devi_nirfana_DAG.py
[2024-06-30T09:23:42.555+0000] {processor.py:161} INFO - Processing /opt/airflow/dags/P2M3_devi_nirfana_DAG.py took 0.456 seconds
[2024-06-30T09:23:53.184+0000] {processor.py:153} INFO - Started process (PID=297) to work on /opt/airflow/dags/P2M3_devi_nirfana_DAG.py
[2024-06-30T09:23:53.185+0000] {processor.py:640} INFO - Processing file /opt/airflow/dags/P2M3_devi_nirfana_DAG.py for tasks to queue
[2024-06-30T09:23:53.187+0000] {logging_mixin.py:115} INFO - [2024-06-30T09:23:53.187+0000] {dagbag.py:508} INFO - Filling up the DagBag from /opt/airflow/dags/P2M3_devi_nirfana_DAG.py
[2024-06-30T09:23:53.582+0000] {logging_mixin.py:115} INFO - [2024-06-30T09:23:53.578+0000] {dagbag.py:321} ERROR - Failed to import: /opt/airflow/dags/P2M3_devi_nirfana_DAG.py
Traceback (most recent call last):
  File "/home/airflow/.local/lib/python3.7/site-packages/sqlalchemy/engine/base.py", line 3243, in _wrap_pool_connect
    return fn()
  File "/home/airflow/.local/lib/python3.7/site-packages/sqlalchemy/pool/base.py", line 310, in connect
    return _ConnectionFairy._checkout(self)
  File "/home/airflow/.local/lib/python3.7/site-packages/sqlalchemy/pool/base.py", line 868, in _checkout
    fairy = _ConnectionRecord.checkout(pool)
  File "/home/airflow/.local/lib/python3.7/site-packages/sqlalchemy/pool/base.py", line 476, in checkout
    rec = pool._do_get()
  File "/home/airflow/.local/lib/python3.7/site-packages/sqlalchemy/pool/impl.py", line 146, in _do_get
    self._dec_overflow()
  File "/home/airflow/.local/lib/python3.7/site-packages/sqlalchemy/util/langhelpers.py", line 72, in __exit__
    with_traceback=exc_tb,
  File "/home/airflow/.local/lib/python3.7/site-packages/sqlalchemy/util/compat.py", line 207, in raise_
    raise exception
  File "/home/airflow/.local/lib/python3.7/site-packages/sqlalchemy/pool/impl.py", line 143, in _do_get
    return self._create_connection()
  File "/home/airflow/.local/lib/python3.7/site-packages/sqlalchemy/pool/base.py", line 256, in _create_connection
    return _ConnectionRecord(self)
  File "/home/airflow/.local/lib/python3.7/site-packages/sqlalchemy/pool/base.py", line 371, in __init__
    self.__connect()
  File "/home/airflow/.local/lib/python3.7/site-packages/sqlalchemy/pool/base.py", line 666, in __connect
    pool.logger.debug("Error on connect(): %s", e)
  File "/home/airflow/.local/lib/python3.7/site-packages/sqlalchemy/util/langhelpers.py", line 72, in __exit__
    with_traceback=exc_tb,
  File "/home/airflow/.local/lib/python3.7/site-packages/sqlalchemy/util/compat.py", line 207, in raise_
    raise exception
  File "/home/airflow/.local/lib/python3.7/site-packages/sqlalchemy/pool/base.py", line 661, in __connect
    self.dbapi_connection = connection = pool._invoke_creator(self)
  File "/home/airflow/.local/lib/python3.7/site-packages/sqlalchemy/engine/create.py", line 590, in connect
    return dialect.connect(*cargs, **cparams)
  File "/home/airflow/.local/lib/python3.7/site-packages/sqlalchemy/engine/default.py", line 584, in connect
    return self.dbapi.connect(*cargs, **cparams)
  File "/home/airflow/.local/lib/python3.7/site-packages/psycopg2/__init__.py", line 122, in connect
    conn = _connect(dsn, connection_factory=connection_factory, **kwasync)
psycopg2.OperationalError: connection to server at "postgres" (172.18.0.3), port 5432 failed: FATAL:  password authentication failed for user "airflow"


The above exception was the direct cause of the following exception:

Traceback (most recent call last):
  File "/home/airflow/.local/lib/python3.7/site-packages/airflow/models/dagbag.py", line 318, in parse
    loader.exec_module(new_module)
  File "<frozen importlib._bootstrap_external>", line 728, in exec_module
  File "<frozen importlib._bootstrap>", line 219, in _call_with_frames_removed
  File "/opt/airflow/dags/P2M3_devi_nirfana_DAG.py", line 28, in <module>
    conn = engine.connect()
  File "/home/airflow/.local/lib/python3.7/site-packages/sqlalchemy/engine/base.py", line 3197, in connect
    return self._connection_cls(self, close_with_result=close_with_result)
  File "/home/airflow/.local/lib/python3.7/site-packages/sqlalchemy/engine/base.py", line 96, in __init__
    else engine.raw_connection()
  File "/home/airflow/.local/lib/python3.7/site-packages/sqlalchemy/engine/base.py", line 3276, in raw_connection
    return self._wrap_pool_connect(self.pool.connect, _connection)
  File "/home/airflow/.local/lib/python3.7/site-packages/sqlalchemy/engine/base.py", line 3247, in _wrap_pool_connect
    e, dialect, self
  File "/home/airflow/.local/lib/python3.7/site-packages/sqlalchemy/engine/base.py", line 2101, in _handle_dbapi_exception_noconnection
    sqlalchemy_exception, with_traceback=exc_info[2], from_=e
  File "/home/airflow/.local/lib/python3.7/site-packages/sqlalchemy/util/compat.py", line 207, in raise_
    raise exception
  File "/home/airflow/.local/lib/python3.7/site-packages/sqlalchemy/engine/base.py", line 3243, in _wrap_pool_connect
    return fn()
  File "/home/airflow/.local/lib/python3.7/site-packages/sqlalchemy/pool/base.py", line 310, in connect
    return _ConnectionFairy._checkout(self)
  File "/home/airflow/.local/lib/python3.7/site-packages/sqlalchemy/pool/base.py", line 868, in _checkout
    fairy = _ConnectionRecord.checkout(pool)
  File "/home/airflow/.local/lib/python3.7/site-packages/sqlalchemy/pool/base.py", line 476, in checkout
    rec = pool._do_get()
  File "/home/airflow/.local/lib/python3.7/site-packages/sqlalchemy/pool/impl.py", line 146, in _do_get
    self._dec_overflow()
  File "/home/airflow/.local/lib/python3.7/site-packages/sqlalchemy/util/langhelpers.py", line 72, in __exit__
    with_traceback=exc_tb,
  File "/home/airflow/.local/lib/python3.7/site-packages/sqlalchemy/util/compat.py", line 207, in raise_
    raise exception
  File "/home/airflow/.local/lib/python3.7/site-packages/sqlalchemy/pool/impl.py", line 143, in _do_get
    return self._create_connection()
  File "/home/airflow/.local/lib/python3.7/site-packages/sqlalchemy/pool/base.py", line 256, in _create_connection
    return _ConnectionRecord(self)
  File "/home/airflow/.local/lib/python3.7/site-packages/sqlalchemy/pool/base.py", line 371, in __init__
    self.__connect()
  File "/home/airflow/.local/lib/python3.7/site-packages/sqlalchemy/pool/base.py", line 666, in __connect
    pool.logger.debug("Error on connect(): %s", e)
  File "/home/airflow/.local/lib/python3.7/site-packages/sqlalchemy/util/langhelpers.py", line 72, in __exit__
    with_traceback=exc_tb,
  File "/home/airflow/.local/lib/python3.7/site-packages/sqlalchemy/util/compat.py", line 207, in raise_
    raise exception
  File "/home/airflow/.local/lib/python3.7/site-packages/sqlalchemy/pool/base.py", line 661, in __connect
    self.dbapi_connection = connection = pool._invoke_creator(self)
  File "/home/airflow/.local/lib/python3.7/site-packages/sqlalchemy/engine/create.py", line 590, in connect
    return dialect.connect(*cargs, **cparams)
  File "/home/airflow/.local/lib/python3.7/site-packages/sqlalchemy/engine/default.py", line 584, in connect
    return self.dbapi.connect(*cargs, **cparams)
  File "/home/airflow/.local/lib/python3.7/site-packages/psycopg2/__init__.py", line 122, in connect
    conn = _connect(dsn, connection_factory=connection_factory, **kwasync)
sqlalchemy.exc.OperationalError: (psycopg2.OperationalError) connection to server at "postgres" (172.18.0.3), port 5432 failed: FATAL:  password authentication failed for user "airflow"

(Background on this error at: https://sqlalche.me/e/14/e3q8)
[2024-06-30T09:23:53.583+0000] {processor.py:652} WARNING - No viable dags retrieved from /opt/airflow/dags/P2M3_devi_nirfana_DAG.py
[2024-06-30T09:23:53.603+0000] {processor.py:161} INFO - Processing /opt/airflow/dags/P2M3_devi_nirfana_DAG.py took 0.423 seconds
[2024-06-30T09:24:23.744+0000] {processor.py:153} INFO - Started process (PID=303) to work on /opt/airflow/dags/P2M3_devi_nirfana_DAG.py
[2024-06-30T09:24:23.748+0000] {processor.py:640} INFO - Processing file /opt/airflow/dags/P2M3_devi_nirfana_DAG.py for tasks to queue
[2024-06-30T09:24:23.752+0000] {logging_mixin.py:115} INFO - [2024-06-30T09:24:23.752+0000] {dagbag.py:508} INFO - Filling up the DagBag from /opt/airflow/dags/P2M3_devi_nirfana_DAG.py
[2024-06-30T09:24:24.532+0000] {logging_mixin.py:115} INFO - [2024-06-30T09:24:24.526+0000] {dagbag.py:321} ERROR - Failed to import: /opt/airflow/dags/P2M3_devi_nirfana_DAG.py
Traceback (most recent call last):
  File "/home/airflow/.local/lib/python3.7/site-packages/sqlalchemy/engine/base.py", line 3243, in _wrap_pool_connect
    return fn()
  File "/home/airflow/.local/lib/python3.7/site-packages/sqlalchemy/pool/base.py", line 310, in connect
    return _ConnectionFairy._checkout(self)
  File "/home/airflow/.local/lib/python3.7/site-packages/sqlalchemy/pool/base.py", line 868, in _checkout
    fairy = _ConnectionRecord.checkout(pool)
  File "/home/airflow/.local/lib/python3.7/site-packages/sqlalchemy/pool/base.py", line 476, in checkout
    rec = pool._do_get()
  File "/home/airflow/.local/lib/python3.7/site-packages/sqlalchemy/pool/impl.py", line 146, in _do_get
    self._dec_overflow()
  File "/home/airflow/.local/lib/python3.7/site-packages/sqlalchemy/util/langhelpers.py", line 72, in __exit__
    with_traceback=exc_tb,
  File "/home/airflow/.local/lib/python3.7/site-packages/sqlalchemy/util/compat.py", line 207, in raise_
    raise exception
  File "/home/airflow/.local/lib/python3.7/site-packages/sqlalchemy/pool/impl.py", line 143, in _do_get
    return self._create_connection()
  File "/home/airflow/.local/lib/python3.7/site-packages/sqlalchemy/pool/base.py", line 256, in _create_connection
    return _ConnectionRecord(self)
  File "/home/airflow/.local/lib/python3.7/site-packages/sqlalchemy/pool/base.py", line 371, in __init__
    self.__connect()
  File "/home/airflow/.local/lib/python3.7/site-packages/sqlalchemy/pool/base.py", line 666, in __connect
    pool.logger.debug("Error on connect(): %s", e)
  File "/home/airflow/.local/lib/python3.7/site-packages/sqlalchemy/util/langhelpers.py", line 72, in __exit__
    with_traceback=exc_tb,
  File "/home/airflow/.local/lib/python3.7/site-packages/sqlalchemy/util/compat.py", line 207, in raise_
    raise exception
  File "/home/airflow/.local/lib/python3.7/site-packages/sqlalchemy/pool/base.py", line 661, in __connect
    self.dbapi_connection = connection = pool._invoke_creator(self)
  File "/home/airflow/.local/lib/python3.7/site-packages/sqlalchemy/engine/create.py", line 590, in connect
    return dialect.connect(*cargs, **cparams)
  File "/home/airflow/.local/lib/python3.7/site-packages/sqlalchemy/engine/default.py", line 584, in connect
    return self.dbapi.connect(*cargs, **cparams)
  File "/home/airflow/.local/lib/python3.7/site-packages/psycopg2/__init__.py", line 122, in connect
    conn = _connect(dsn, connection_factory=connection_factory, **kwasync)
psycopg2.OperationalError: connection to server at "postgres" (172.18.0.3), port 5432 failed: FATAL:  password authentication failed for user "airflow"


The above exception was the direct cause of the following exception:

Traceback (most recent call last):
  File "/home/airflow/.local/lib/python3.7/site-packages/airflow/models/dagbag.py", line 318, in parse
    loader.exec_module(new_module)
  File "<frozen importlib._bootstrap_external>", line 728, in exec_module
  File "<frozen importlib._bootstrap>", line 219, in _call_with_frames_removed
  File "/opt/airflow/dags/P2M3_devi_nirfana_DAG.py", line 28, in <module>
    conn = engine.connect()
  File "/home/airflow/.local/lib/python3.7/site-packages/sqlalchemy/engine/base.py", line 3197, in connect
    return self._connection_cls(self, close_with_result=close_with_result)
  File "/home/airflow/.local/lib/python3.7/site-packages/sqlalchemy/engine/base.py", line 96, in __init__
    else engine.raw_connection()
  File "/home/airflow/.local/lib/python3.7/site-packages/sqlalchemy/engine/base.py", line 3276, in raw_connection
    return self._wrap_pool_connect(self.pool.connect, _connection)
  File "/home/airflow/.local/lib/python3.7/site-packages/sqlalchemy/engine/base.py", line 3247, in _wrap_pool_connect
    e, dialect, self
  File "/home/airflow/.local/lib/python3.7/site-packages/sqlalchemy/engine/base.py", line 2101, in _handle_dbapi_exception_noconnection
    sqlalchemy_exception, with_traceback=exc_info[2], from_=e
  File "/home/airflow/.local/lib/python3.7/site-packages/sqlalchemy/util/compat.py", line 207, in raise_
    raise exception
  File "/home/airflow/.local/lib/python3.7/site-packages/sqlalchemy/engine/base.py", line 3243, in _wrap_pool_connect
    return fn()
  File "/home/airflow/.local/lib/python3.7/site-packages/sqlalchemy/pool/base.py", line 310, in connect
    return _ConnectionFairy._checkout(self)
  File "/home/airflow/.local/lib/python3.7/site-packages/sqlalchemy/pool/base.py", line 868, in _checkout
    fairy = _ConnectionRecord.checkout(pool)
  File "/home/airflow/.local/lib/python3.7/site-packages/sqlalchemy/pool/base.py", line 476, in checkout
    rec = pool._do_get()
  File "/home/airflow/.local/lib/python3.7/site-packages/sqlalchemy/pool/impl.py", line 146, in _do_get
    self._dec_overflow()
  File "/home/airflow/.local/lib/python3.7/site-packages/sqlalchemy/util/langhelpers.py", line 72, in __exit__
    with_traceback=exc_tb,
  File "/home/airflow/.local/lib/python3.7/site-packages/sqlalchemy/util/compat.py", line 207, in raise_
    raise exception
  File "/home/airflow/.local/lib/python3.7/site-packages/sqlalchemy/pool/impl.py", line 143, in _do_get
    return self._create_connection()
  File "/home/airflow/.local/lib/python3.7/site-packages/sqlalchemy/pool/base.py", line 256, in _create_connection
    return _ConnectionRecord(self)
  File "/home/airflow/.local/lib/python3.7/site-packages/sqlalchemy/pool/base.py", line 371, in __init__
    self.__connect()
  File "/home/airflow/.local/lib/python3.7/site-packages/sqlalchemy/pool/base.py", line 666, in __connect
    pool.logger.debug("Error on connect(): %s", e)
  File "/home/airflow/.local/lib/python3.7/site-packages/sqlalchemy/util/langhelpers.py", line 72, in __exit__
    with_traceback=exc_tb,
  File "/home/airflow/.local/lib/python3.7/site-packages/sqlalchemy/util/compat.py", line 207, in raise_
    raise exception
  File "/home/airflow/.local/lib/python3.7/site-packages/sqlalchemy/pool/base.py", line 661, in __connect
    self.dbapi_connection = connection = pool._invoke_creator(self)
  File "/home/airflow/.local/lib/python3.7/site-packages/sqlalchemy/engine/create.py", line 590, in connect
    return dialect.connect(*cargs, **cparams)
  File "/home/airflow/.local/lib/python3.7/site-packages/sqlalchemy/engine/default.py", line 584, in connect
    return self.dbapi.connect(*cargs, **cparams)
  File "/home/airflow/.local/lib/python3.7/site-packages/psycopg2/__init__.py", line 122, in connect
    conn = _connect(dsn, connection_factory=connection_factory, **kwasync)
sqlalchemy.exc.OperationalError: (psycopg2.OperationalError) connection to server at "postgres" (172.18.0.3), port 5432 failed: FATAL:  password authentication failed for user "airflow"

(Background on this error at: https://sqlalche.me/e/14/e3q8)
[2024-06-30T09:24:24.535+0000] {processor.py:652} WARNING - No viable dags retrieved from /opt/airflow/dags/P2M3_devi_nirfana_DAG.py
[2024-06-30T09:24:24.559+0000] {processor.py:161} INFO - Processing /opt/airflow/dags/P2M3_devi_nirfana_DAG.py took 0.819 seconds
[2024-06-30T09:24:54.691+0000] {processor.py:153} INFO - Started process (PID=309) to work on /opt/airflow/dags/P2M3_devi_nirfana_DAG.py
[2024-06-30T09:24:54.692+0000] {processor.py:640} INFO - Processing file /opt/airflow/dags/P2M3_devi_nirfana_DAG.py for tasks to queue
[2024-06-30T09:24:54.694+0000] {logging_mixin.py:115} INFO - [2024-06-30T09:24:54.693+0000] {dagbag.py:508} INFO - Filling up the DagBag from /opt/airflow/dags/P2M3_devi_nirfana_DAG.py
[2024-06-30T09:24:55.396+0000] {logging_mixin.py:115} INFO - [2024-06-30T09:24:55.390+0000] {dagbag.py:321} ERROR - Failed to import: /opt/airflow/dags/P2M3_devi_nirfana_DAG.py
Traceback (most recent call last):
  File "/home/airflow/.local/lib/python3.7/site-packages/sqlalchemy/engine/base.py", line 3243, in _wrap_pool_connect
    return fn()
  File "/home/airflow/.local/lib/python3.7/site-packages/sqlalchemy/pool/base.py", line 310, in connect
    return _ConnectionFairy._checkout(self)
  File "/home/airflow/.local/lib/python3.7/site-packages/sqlalchemy/pool/base.py", line 868, in _checkout
    fairy = _ConnectionRecord.checkout(pool)
  File "/home/airflow/.local/lib/python3.7/site-packages/sqlalchemy/pool/base.py", line 476, in checkout
    rec = pool._do_get()
  File "/home/airflow/.local/lib/python3.7/site-packages/sqlalchemy/pool/impl.py", line 146, in _do_get
    self._dec_overflow()
  File "/home/airflow/.local/lib/python3.7/site-packages/sqlalchemy/util/langhelpers.py", line 72, in __exit__
    with_traceback=exc_tb,
  File "/home/airflow/.local/lib/python3.7/site-packages/sqlalchemy/util/compat.py", line 207, in raise_
    raise exception
  File "/home/airflow/.local/lib/python3.7/site-packages/sqlalchemy/pool/impl.py", line 143, in _do_get
    return self._create_connection()
  File "/home/airflow/.local/lib/python3.7/site-packages/sqlalchemy/pool/base.py", line 256, in _create_connection
    return _ConnectionRecord(self)
  File "/home/airflow/.local/lib/python3.7/site-packages/sqlalchemy/pool/base.py", line 371, in __init__
    self.__connect()
  File "/home/airflow/.local/lib/python3.7/site-packages/sqlalchemy/pool/base.py", line 666, in __connect
    pool.logger.debug("Error on connect(): %s", e)
  File "/home/airflow/.local/lib/python3.7/site-packages/sqlalchemy/util/langhelpers.py", line 72, in __exit__
    with_traceback=exc_tb,
  File "/home/airflow/.local/lib/python3.7/site-packages/sqlalchemy/util/compat.py", line 207, in raise_
    raise exception
  File "/home/airflow/.local/lib/python3.7/site-packages/sqlalchemy/pool/base.py", line 661, in __connect
    self.dbapi_connection = connection = pool._invoke_creator(self)
  File "/home/airflow/.local/lib/python3.7/site-packages/sqlalchemy/engine/create.py", line 590, in connect
    return dialect.connect(*cargs, **cparams)
  File "/home/airflow/.local/lib/python3.7/site-packages/sqlalchemy/engine/default.py", line 584, in connect
    return self.dbapi.connect(*cargs, **cparams)
  File "/home/airflow/.local/lib/python3.7/site-packages/psycopg2/__init__.py", line 122, in connect
    conn = _connect(dsn, connection_factory=connection_factory, **kwasync)
psycopg2.OperationalError: connection to server at "postgres" (172.18.0.3), port 5432 failed: FATAL:  password authentication failed for user "airflow"


The above exception was the direct cause of the following exception:

Traceback (most recent call last):
  File "/home/airflow/.local/lib/python3.7/site-packages/airflow/models/dagbag.py", line 318, in parse
    loader.exec_module(new_module)
  File "<frozen importlib._bootstrap_external>", line 728, in exec_module
  File "<frozen importlib._bootstrap>", line 219, in _call_with_frames_removed
  File "/opt/airflow/dags/P2M3_devi_nirfana_DAG.py", line 28, in <module>
    conn = engine.connect()
  File "/home/airflow/.local/lib/python3.7/site-packages/sqlalchemy/engine/base.py", line 3197, in connect
    return self._connection_cls(self, close_with_result=close_with_result)
  File "/home/airflow/.local/lib/python3.7/site-packages/sqlalchemy/engine/base.py", line 96, in __init__
    else engine.raw_connection()
  File "/home/airflow/.local/lib/python3.7/site-packages/sqlalchemy/engine/base.py", line 3276, in raw_connection
    return self._wrap_pool_connect(self.pool.connect, _connection)
  File "/home/airflow/.local/lib/python3.7/site-packages/sqlalchemy/engine/base.py", line 3247, in _wrap_pool_connect
    e, dialect, self
  File "/home/airflow/.local/lib/python3.7/site-packages/sqlalchemy/engine/base.py", line 2101, in _handle_dbapi_exception_noconnection
    sqlalchemy_exception, with_traceback=exc_info[2], from_=e
  File "/home/airflow/.local/lib/python3.7/site-packages/sqlalchemy/util/compat.py", line 207, in raise_
    raise exception
  File "/home/airflow/.local/lib/python3.7/site-packages/sqlalchemy/engine/base.py", line 3243, in _wrap_pool_connect
    return fn()
  File "/home/airflow/.local/lib/python3.7/site-packages/sqlalchemy/pool/base.py", line 310, in connect
    return _ConnectionFairy._checkout(self)
  File "/home/airflow/.local/lib/python3.7/site-packages/sqlalchemy/pool/base.py", line 868, in _checkout
    fairy = _ConnectionRecord.checkout(pool)
  File "/home/airflow/.local/lib/python3.7/site-packages/sqlalchemy/pool/base.py", line 476, in checkout
    rec = pool._do_get()
  File "/home/airflow/.local/lib/python3.7/site-packages/sqlalchemy/pool/impl.py", line 146, in _do_get
    self._dec_overflow()
  File "/home/airflow/.local/lib/python3.7/site-packages/sqlalchemy/util/langhelpers.py", line 72, in __exit__
    with_traceback=exc_tb,
  File "/home/airflow/.local/lib/python3.7/site-packages/sqlalchemy/util/compat.py", line 207, in raise_
    raise exception
  File "/home/airflow/.local/lib/python3.7/site-packages/sqlalchemy/pool/impl.py", line 143, in _do_get
    return self._create_connection()
  File "/home/airflow/.local/lib/python3.7/site-packages/sqlalchemy/pool/base.py", line 256, in _create_connection
    return _ConnectionRecord(self)
  File "/home/airflow/.local/lib/python3.7/site-packages/sqlalchemy/pool/base.py", line 371, in __init__
    self.__connect()
  File "/home/airflow/.local/lib/python3.7/site-packages/sqlalchemy/pool/base.py", line 666, in __connect
    pool.logger.debug("Error on connect(): %s", e)
  File "/home/airflow/.local/lib/python3.7/site-packages/sqlalchemy/util/langhelpers.py", line 72, in __exit__
    with_traceback=exc_tb,
  File "/home/airflow/.local/lib/python3.7/site-packages/sqlalchemy/util/compat.py", line 207, in raise_
    raise exception
  File "/home/airflow/.local/lib/python3.7/site-packages/sqlalchemy/pool/base.py", line 661, in __connect
    self.dbapi_connection = connection = pool._invoke_creator(self)
  File "/home/airflow/.local/lib/python3.7/site-packages/sqlalchemy/engine/create.py", line 590, in connect
    return dialect.connect(*cargs, **cparams)
  File "/home/airflow/.local/lib/python3.7/site-packages/sqlalchemy/engine/default.py", line 584, in connect
    return self.dbapi.connect(*cargs, **cparams)
  File "/home/airflow/.local/lib/python3.7/site-packages/psycopg2/__init__.py", line 122, in connect
    conn = _connect(dsn, connection_factory=connection_factory, **kwasync)
sqlalchemy.exc.OperationalError: (psycopg2.OperationalError) connection to server at "postgres" (172.18.0.3), port 5432 failed: FATAL:  password authentication failed for user "airflow"

(Background on this error at: https://sqlalche.me/e/14/e3q8)
[2024-06-30T09:24:55.398+0000] {processor.py:652} WARNING - No viable dags retrieved from /opt/airflow/dags/P2M3_devi_nirfana_DAG.py
[2024-06-30T09:24:55.426+0000] {processor.py:161} INFO - Processing /opt/airflow/dags/P2M3_devi_nirfana_DAG.py took 0.740 seconds
[2024-06-30T09:24:59.471+0000] {processor.py:153} INFO - Started process (PID=315) to work on /opt/airflow/dags/P2M3_devi_nirfana_DAG.py
[2024-06-30T09:24:59.472+0000] {processor.py:640} INFO - Processing file /opt/airflow/dags/P2M3_devi_nirfana_DAG.py for tasks to queue
[2024-06-30T09:24:59.473+0000] {logging_mixin.py:115} INFO - [2024-06-30T09:24:59.473+0000] {dagbag.py:508} INFO - Filling up the DagBag from /opt/airflow/dags/P2M3_devi_nirfana_DAG.py
[2024-06-30T09:24:59.949+0000] {logging_mixin.py:115} INFO - [2024-06-30T09:24:59.940+0000] {dagbag.py:321} ERROR - Failed to import: /opt/airflow/dags/P2M3_devi_nirfana_DAG.py
Traceback (most recent call last):
  File "/home/airflow/.local/lib/python3.7/site-packages/sqlalchemy/engine/base.py", line 3243, in _wrap_pool_connect
    return fn()
  File "/home/airflow/.local/lib/python3.7/site-packages/sqlalchemy/pool/base.py", line 310, in connect
    return _ConnectionFairy._checkout(self)
  File "/home/airflow/.local/lib/python3.7/site-packages/sqlalchemy/pool/base.py", line 868, in _checkout
    fairy = _ConnectionRecord.checkout(pool)
  File "/home/airflow/.local/lib/python3.7/site-packages/sqlalchemy/pool/base.py", line 476, in checkout
    rec = pool._do_get()
  File "/home/airflow/.local/lib/python3.7/site-packages/sqlalchemy/pool/impl.py", line 146, in _do_get
    self._dec_overflow()
  File "/home/airflow/.local/lib/python3.7/site-packages/sqlalchemy/util/langhelpers.py", line 72, in __exit__
    with_traceback=exc_tb,
  File "/home/airflow/.local/lib/python3.7/site-packages/sqlalchemy/util/compat.py", line 207, in raise_
    raise exception
  File "/home/airflow/.local/lib/python3.7/site-packages/sqlalchemy/pool/impl.py", line 143, in _do_get
    return self._create_connection()
  File "/home/airflow/.local/lib/python3.7/site-packages/sqlalchemy/pool/base.py", line 256, in _create_connection
    return _ConnectionRecord(self)
  File "/home/airflow/.local/lib/python3.7/site-packages/sqlalchemy/pool/base.py", line 371, in __init__
    self.__connect()
  File "/home/airflow/.local/lib/python3.7/site-packages/sqlalchemy/pool/base.py", line 666, in __connect
    pool.logger.debug("Error on connect(): %s", e)
  File "/home/airflow/.local/lib/python3.7/site-packages/sqlalchemy/util/langhelpers.py", line 72, in __exit__
    with_traceback=exc_tb,
  File "/home/airflow/.local/lib/python3.7/site-packages/sqlalchemy/util/compat.py", line 207, in raise_
    raise exception
  File "/home/airflow/.local/lib/python3.7/site-packages/sqlalchemy/pool/base.py", line 661, in __connect
    self.dbapi_connection = connection = pool._invoke_creator(self)
  File "/home/airflow/.local/lib/python3.7/site-packages/sqlalchemy/engine/create.py", line 590, in connect
    return dialect.connect(*cargs, **cparams)
  File "/home/airflow/.local/lib/python3.7/site-packages/sqlalchemy/engine/default.py", line 584, in connect
    return self.dbapi.connect(*cargs, **cparams)
  File "/home/airflow/.local/lib/python3.7/site-packages/psycopg2/__init__.py", line 122, in connect
    conn = _connect(dsn, connection_factory=connection_factory, **kwasync)
psycopg2.OperationalError: connection to server at "postgres" (172.18.0.3), port 5432 failed: FATAL:  password authentication failed for user "airflow"


The above exception was the direct cause of the following exception:

Traceback (most recent call last):
  File "/home/airflow/.local/lib/python3.7/site-packages/airflow/models/dagbag.py", line 318, in parse
    loader.exec_module(new_module)
  File "<frozen importlib._bootstrap_external>", line 728, in exec_module
  File "<frozen importlib._bootstrap>", line 219, in _call_with_frames_removed
  File "/opt/airflow/dags/P2M3_devi_nirfana_DAG.py", line 28, in <module>
    conn = engine.connect()
  File "/home/airflow/.local/lib/python3.7/site-packages/sqlalchemy/engine/base.py", line 3197, in connect
    return self._connection_cls(self, close_with_result=close_with_result)
  File "/home/airflow/.local/lib/python3.7/site-packages/sqlalchemy/engine/base.py", line 96, in __init__
    else engine.raw_connection()
  File "/home/airflow/.local/lib/python3.7/site-packages/sqlalchemy/engine/base.py", line 3276, in raw_connection
    return self._wrap_pool_connect(self.pool.connect, _connection)
  File "/home/airflow/.local/lib/python3.7/site-packages/sqlalchemy/engine/base.py", line 3247, in _wrap_pool_connect
    e, dialect, self
  File "/home/airflow/.local/lib/python3.7/site-packages/sqlalchemy/engine/base.py", line 2101, in _handle_dbapi_exception_noconnection
    sqlalchemy_exception, with_traceback=exc_info[2], from_=e
  File "/home/airflow/.local/lib/python3.7/site-packages/sqlalchemy/util/compat.py", line 207, in raise_
    raise exception
  File "/home/airflow/.local/lib/python3.7/site-packages/sqlalchemy/engine/base.py", line 3243, in _wrap_pool_connect
    return fn()
  File "/home/airflow/.local/lib/python3.7/site-packages/sqlalchemy/pool/base.py", line 310, in connect
    return _ConnectionFairy._checkout(self)
  File "/home/airflow/.local/lib/python3.7/site-packages/sqlalchemy/pool/base.py", line 868, in _checkout
    fairy = _ConnectionRecord.checkout(pool)
  File "/home/airflow/.local/lib/python3.7/site-packages/sqlalchemy/pool/base.py", line 476, in checkout
    rec = pool._do_get()
  File "/home/airflow/.local/lib/python3.7/site-packages/sqlalchemy/pool/impl.py", line 146, in _do_get
    self._dec_overflow()
  File "/home/airflow/.local/lib/python3.7/site-packages/sqlalchemy/util/langhelpers.py", line 72, in __exit__
    with_traceback=exc_tb,
  File "/home/airflow/.local/lib/python3.7/site-packages/sqlalchemy/util/compat.py", line 207, in raise_
    raise exception
  File "/home/airflow/.local/lib/python3.7/site-packages/sqlalchemy/pool/impl.py", line 143, in _do_get
    return self._create_connection()
  File "/home/airflow/.local/lib/python3.7/site-packages/sqlalchemy/pool/base.py", line 256, in _create_connection
    return _ConnectionRecord(self)
  File "/home/airflow/.local/lib/python3.7/site-packages/sqlalchemy/pool/base.py", line 371, in __init__
    self.__connect()
  File "/home/airflow/.local/lib/python3.7/site-packages/sqlalchemy/pool/base.py", line 666, in __connect
    pool.logger.debug("Error on connect(): %s", e)
  File "/home/airflow/.local/lib/python3.7/site-packages/sqlalchemy/util/langhelpers.py", line 72, in __exit__
    with_traceback=exc_tb,
  File "/home/airflow/.local/lib/python3.7/site-packages/sqlalchemy/util/compat.py", line 207, in raise_
    raise exception
  File "/home/airflow/.local/lib/python3.7/site-packages/sqlalchemy/pool/base.py", line 661, in __connect
    self.dbapi_connection = connection = pool._invoke_creator(self)
  File "/home/airflow/.local/lib/python3.7/site-packages/sqlalchemy/engine/create.py", line 590, in connect
    return dialect.connect(*cargs, **cparams)
  File "/home/airflow/.local/lib/python3.7/site-packages/sqlalchemy/engine/default.py", line 584, in connect
    return self.dbapi.connect(*cargs, **cparams)
  File "/home/airflow/.local/lib/python3.7/site-packages/psycopg2/__init__.py", line 122, in connect
    conn = _connect(dsn, connection_factory=connection_factory, **kwasync)
sqlalchemy.exc.OperationalError: (psycopg2.OperationalError) connection to server at "postgres" (172.18.0.3), port 5432 failed: FATAL:  password authentication failed for user "airflow"

(Background on this error at: https://sqlalche.me/e/14/e3q8)
[2024-06-30T09:24:59.952+0000] {processor.py:652} WARNING - No viable dags retrieved from /opt/airflow/dags/P2M3_devi_nirfana_DAG.py
[2024-06-30T09:24:59.989+0000] {processor.py:161} INFO - Processing /opt/airflow/dags/P2M3_devi_nirfana_DAG.py took 0.522 seconds
[2024-06-30T09:25:03.889+0000] {processor.py:153} INFO - Started process (PID=321) to work on /opt/airflow/dags/P2M3_devi_nirfana_DAG.py
[2024-06-30T09:25:03.891+0000] {processor.py:640} INFO - Processing file /opt/airflow/dags/P2M3_devi_nirfana_DAG.py for tasks to queue
[2024-06-30T09:25:03.892+0000] {logging_mixin.py:115} INFO - [2024-06-30T09:25:03.892+0000] {dagbag.py:508} INFO - Filling up the DagBag from /opt/airflow/dags/P2M3_devi_nirfana_DAG.py
[2024-06-30T09:25:04.332+0000] {logging_mixin.py:115} INFO - [2024-06-30T09:25:04.327+0000] {dagbag.py:321} ERROR - Failed to import: /opt/airflow/dags/P2M3_devi_nirfana_DAG.py
Traceback (most recent call last):
  File "/home/airflow/.local/lib/python3.7/site-packages/sqlalchemy/engine/base.py", line 3243, in _wrap_pool_connect
    return fn()
  File "/home/airflow/.local/lib/python3.7/site-packages/sqlalchemy/pool/base.py", line 310, in connect
    return _ConnectionFairy._checkout(self)
  File "/home/airflow/.local/lib/python3.7/site-packages/sqlalchemy/pool/base.py", line 868, in _checkout
    fairy = _ConnectionRecord.checkout(pool)
  File "/home/airflow/.local/lib/python3.7/site-packages/sqlalchemy/pool/base.py", line 476, in checkout
    rec = pool._do_get()
  File "/home/airflow/.local/lib/python3.7/site-packages/sqlalchemy/pool/impl.py", line 146, in _do_get
    self._dec_overflow()
  File "/home/airflow/.local/lib/python3.7/site-packages/sqlalchemy/util/langhelpers.py", line 72, in __exit__
    with_traceback=exc_tb,
  File "/home/airflow/.local/lib/python3.7/site-packages/sqlalchemy/util/compat.py", line 207, in raise_
    raise exception
  File "/home/airflow/.local/lib/python3.7/site-packages/sqlalchemy/pool/impl.py", line 143, in _do_get
    return self._create_connection()
  File "/home/airflow/.local/lib/python3.7/site-packages/sqlalchemy/pool/base.py", line 256, in _create_connection
    return _ConnectionRecord(self)
  File "/home/airflow/.local/lib/python3.7/site-packages/sqlalchemy/pool/base.py", line 371, in __init__
    self.__connect()
  File "/home/airflow/.local/lib/python3.7/site-packages/sqlalchemy/pool/base.py", line 666, in __connect
    pool.logger.debug("Error on connect(): %s", e)
  File "/home/airflow/.local/lib/python3.7/site-packages/sqlalchemy/util/langhelpers.py", line 72, in __exit__
    with_traceback=exc_tb,
  File "/home/airflow/.local/lib/python3.7/site-packages/sqlalchemy/util/compat.py", line 207, in raise_
    raise exception
  File "/home/airflow/.local/lib/python3.7/site-packages/sqlalchemy/pool/base.py", line 661, in __connect
    self.dbapi_connection = connection = pool._invoke_creator(self)
  File "/home/airflow/.local/lib/python3.7/site-packages/sqlalchemy/engine/create.py", line 590, in connect
    return dialect.connect(*cargs, **cparams)
  File "/home/airflow/.local/lib/python3.7/site-packages/sqlalchemy/engine/default.py", line 584, in connect
    return self.dbapi.connect(*cargs, **cparams)
  File "/home/airflow/.local/lib/python3.7/site-packages/psycopg2/__init__.py", line 122, in connect
    conn = _connect(dsn, connection_factory=connection_factory, **kwasync)
psycopg2.OperationalError: connection to server at "postgres" (172.18.0.3), port 5432 failed: FATAL:  password authentication failed for user "airflow"


The above exception was the direct cause of the following exception:

Traceback (most recent call last):
  File "/home/airflow/.local/lib/python3.7/site-packages/airflow/models/dagbag.py", line 318, in parse
    loader.exec_module(new_module)
  File "<frozen importlib._bootstrap_external>", line 728, in exec_module
  File "<frozen importlib._bootstrap>", line 219, in _call_with_frames_removed
  File "/opt/airflow/dags/P2M3_devi_nirfana_DAG.py", line 28, in <module>
    conn = engine.connect()
  File "/home/airflow/.local/lib/python3.7/site-packages/sqlalchemy/engine/base.py", line 3197, in connect
    return self._connection_cls(self, close_with_result=close_with_result)
  File "/home/airflow/.local/lib/python3.7/site-packages/sqlalchemy/engine/base.py", line 96, in __init__
    else engine.raw_connection()
  File "/home/airflow/.local/lib/python3.7/site-packages/sqlalchemy/engine/base.py", line 3276, in raw_connection
    return self._wrap_pool_connect(self.pool.connect, _connection)
  File "/home/airflow/.local/lib/python3.7/site-packages/sqlalchemy/engine/base.py", line 3247, in _wrap_pool_connect
    e, dialect, self
  File "/home/airflow/.local/lib/python3.7/site-packages/sqlalchemy/engine/base.py", line 2101, in _handle_dbapi_exception_noconnection
    sqlalchemy_exception, with_traceback=exc_info[2], from_=e
  File "/home/airflow/.local/lib/python3.7/site-packages/sqlalchemy/util/compat.py", line 207, in raise_
    raise exception
  File "/home/airflow/.local/lib/python3.7/site-packages/sqlalchemy/engine/base.py", line 3243, in _wrap_pool_connect
    return fn()
  File "/home/airflow/.local/lib/python3.7/site-packages/sqlalchemy/pool/base.py", line 310, in connect
    return _ConnectionFairy._checkout(self)
  File "/home/airflow/.local/lib/python3.7/site-packages/sqlalchemy/pool/base.py", line 868, in _checkout
    fairy = _ConnectionRecord.checkout(pool)
  File "/home/airflow/.local/lib/python3.7/site-packages/sqlalchemy/pool/base.py", line 476, in checkout
    rec = pool._do_get()
  File "/home/airflow/.local/lib/python3.7/site-packages/sqlalchemy/pool/impl.py", line 146, in _do_get
    self._dec_overflow()
  File "/home/airflow/.local/lib/python3.7/site-packages/sqlalchemy/util/langhelpers.py", line 72, in __exit__
    with_traceback=exc_tb,
  File "/home/airflow/.local/lib/python3.7/site-packages/sqlalchemy/util/compat.py", line 207, in raise_
    raise exception
  File "/home/airflow/.local/lib/python3.7/site-packages/sqlalchemy/pool/impl.py", line 143, in _do_get
    return self._create_connection()
  File "/home/airflow/.local/lib/python3.7/site-packages/sqlalchemy/pool/base.py", line 256, in _create_connection
    return _ConnectionRecord(self)
  File "/home/airflow/.local/lib/python3.7/site-packages/sqlalchemy/pool/base.py", line 371, in __init__
    self.__connect()
  File "/home/airflow/.local/lib/python3.7/site-packages/sqlalchemy/pool/base.py", line 666, in __connect
    pool.logger.debug("Error on connect(): %s", e)
  File "/home/airflow/.local/lib/python3.7/site-packages/sqlalchemy/util/langhelpers.py", line 72, in __exit__
    with_traceback=exc_tb,
  File "/home/airflow/.local/lib/python3.7/site-packages/sqlalchemy/util/compat.py", line 207, in raise_
    raise exception
  File "/home/airflow/.local/lib/python3.7/site-packages/sqlalchemy/pool/base.py", line 661, in __connect
    self.dbapi_connection = connection = pool._invoke_creator(self)
  File "/home/airflow/.local/lib/python3.7/site-packages/sqlalchemy/engine/create.py", line 590, in connect
    return dialect.connect(*cargs, **cparams)
  File "/home/airflow/.local/lib/python3.7/site-packages/sqlalchemy/engine/default.py", line 584, in connect
    return self.dbapi.connect(*cargs, **cparams)
  File "/home/airflow/.local/lib/python3.7/site-packages/psycopg2/__init__.py", line 122, in connect
    conn = _connect(dsn, connection_factory=connection_factory, **kwasync)
sqlalchemy.exc.OperationalError: (psycopg2.OperationalError) connection to server at "postgres" (172.18.0.3), port 5432 failed: FATAL:  password authentication failed for user "airflow"

(Background on this error at: https://sqlalche.me/e/14/e3q8)
[2024-06-30T09:25:04.333+0000] {processor.py:652} WARNING - No viable dags retrieved from /opt/airflow/dags/P2M3_devi_nirfana_DAG.py
[2024-06-30T09:25:04.354+0000] {processor.py:161} INFO - Processing /opt/airflow/dags/P2M3_devi_nirfana_DAG.py took 0.469 seconds
[2024-06-30T09:28:39.087+0000] {processor.py:153} INFO - Started process (PID=182) to work on /opt/airflow/dags/P2M3_devi_nirfana_DAG.py
[2024-06-30T09:28:39.088+0000] {processor.py:640} INFO - Processing file /opt/airflow/dags/P2M3_devi_nirfana_DAG.py for tasks to queue
[2024-06-30T09:28:39.089+0000] {logging_mixin.py:115} INFO - [2024-06-30T09:28:39.089+0000] {dagbag.py:508} INFO - Filling up the DagBag from /opt/airflow/dags/P2M3_devi_nirfana_DAG.py
[2024-06-30T09:28:39.478+0000] {processor.py:650} INFO - DAG(s) dict_keys(['Milestones3']) retrieved from /opt/airflow/dags/P2M3_devi_nirfana_DAG.py
[2024-06-30T09:28:39.554+0000] {logging_mixin.py:115} INFO - [2024-06-30T09:28:39.554+0000] {manager.py:508} INFO - Created Permission View: can read on DAG:Milestones3
[2024-06-30T09:28:39.565+0000] {logging_mixin.py:115} INFO - [2024-06-30T09:28:39.565+0000] {manager.py:508} INFO - Created Permission View: can edit on DAG:Milestones3
[2024-06-30T09:28:39.575+0000] {logging_mixin.py:115} INFO - [2024-06-30T09:28:39.575+0000] {manager.py:508} INFO - Created Permission View: can delete on DAG:Milestones3
[2024-06-30T09:28:39.576+0000] {logging_mixin.py:115} INFO - [2024-06-30T09:28:39.576+0000] {dag.py:2429} INFO - Sync 1 DAGs
[2024-06-30T09:28:39.585+0000] {logging_mixin.py:115} INFO - [2024-06-30T09:28:39.585+0000] {dag.py:2448} INFO - Creating ORM DAG for Milestones3
[2024-06-30T09:28:39.600+0000] {logging_mixin.py:115} INFO - [2024-06-30T09:28:39.600+0000] {dag.py:2981} INFO - Setting next_dagrun for Milestones3 to 2024-06-19T06:30:00+00:00, run_after=2024-06-20T06:30:00+00:00
[2024-06-30T09:28:39.617+0000] {processor.py:161} INFO - Processing /opt/airflow/dags/P2M3_devi_nirfana_DAG.py took 0.534 seconds
[2024-06-30T09:29:09.733+0000] {processor.py:153} INFO - Started process (PID=189) to work on /opt/airflow/dags/P2M3_devi_nirfana_DAG.py
[2024-06-30T09:29:09.734+0000] {processor.py:640} INFO - Processing file /opt/airflow/dags/P2M3_devi_nirfana_DAG.py for tasks to queue
[2024-06-30T09:29:09.735+0000] {logging_mixin.py:115} INFO - [2024-06-30T09:29:09.735+0000] {dagbag.py:508} INFO - Filling up the DagBag from /opt/airflow/dags/P2M3_devi_nirfana_DAG.py
[2024-06-30T09:29:10.161+0000] {processor.py:650} INFO - DAG(s) dict_keys(['Milestones3']) retrieved from /opt/airflow/dags/P2M3_devi_nirfana_DAG.py
[2024-06-30T09:29:10.182+0000] {logging_mixin.py:115} INFO - [2024-06-30T09:29:10.182+0000] {dag.py:2429} INFO - Sync 1 DAGs
[2024-06-30T09:29:10.204+0000] {logging_mixin.py:115} INFO - [2024-06-30T09:29:10.204+0000] {dag.py:2981} INFO - Setting next_dagrun for Milestones3 to 2024-06-19T06:30:00+00:00, run_after=2024-06-20T06:30:00+00:00
[2024-06-30T09:29:10.218+0000] {processor.py:161} INFO - Processing /opt/airflow/dags/P2M3_devi_nirfana_DAG.py took 0.490 seconds
[2024-06-30T09:29:40.338+0000] {processor.py:153} INFO - Started process (PID=195) to work on /opt/airflow/dags/P2M3_devi_nirfana_DAG.py
[2024-06-30T09:29:40.339+0000] {processor.py:640} INFO - Processing file /opt/airflow/dags/P2M3_devi_nirfana_DAG.py for tasks to queue
[2024-06-30T09:29:40.340+0000] {logging_mixin.py:115} INFO - [2024-06-30T09:29:40.340+0000] {dagbag.py:508} INFO - Filling up the DagBag from /opt/airflow/dags/P2M3_devi_nirfana_DAG.py
[2024-06-30T09:29:40.740+0000] {processor.py:650} INFO - DAG(s) dict_keys(['Milestones3']) retrieved from /opt/airflow/dags/P2M3_devi_nirfana_DAG.py
[2024-06-30T09:29:40.762+0000] {logging_mixin.py:115} INFO - [2024-06-30T09:29:40.761+0000] {dag.py:2429} INFO - Sync 1 DAGs
[2024-06-30T09:29:40.789+0000] {logging_mixin.py:115} INFO - [2024-06-30T09:29:40.789+0000] {dag.py:2981} INFO - Setting next_dagrun for Milestones3 to 2024-06-19T06:30:00+00:00, run_after=2024-06-20T06:30:00+00:00
[2024-06-30T09:29:40.804+0000] {processor.py:161} INFO - Processing /opt/airflow/dags/P2M3_devi_nirfana_DAG.py took 0.470 seconds
[2024-06-30T09:30:10.927+0000] {processor.py:153} INFO - Started process (PID=201) to work on /opt/airflow/dags/P2M3_devi_nirfana_DAG.py
[2024-06-30T09:30:10.928+0000] {processor.py:640} INFO - Processing file /opt/airflow/dags/P2M3_devi_nirfana_DAG.py for tasks to queue
[2024-06-30T09:30:10.930+0000] {logging_mixin.py:115} INFO - [2024-06-30T09:30:10.929+0000] {dagbag.py:508} INFO - Filling up the DagBag from /opt/airflow/dags/P2M3_devi_nirfana_DAG.py
[2024-06-30T09:30:11.290+0000] {processor.py:650} INFO - DAG(s) dict_keys(['Milestones3']) retrieved from /opt/airflow/dags/P2M3_devi_nirfana_DAG.py
[2024-06-30T09:30:11.312+0000] {logging_mixin.py:115} INFO - [2024-06-30T09:30:11.311+0000] {dag.py:2429} INFO - Sync 1 DAGs
[2024-06-30T09:30:11.334+0000] {logging_mixin.py:115} INFO - [2024-06-30T09:30:11.333+0000] {dag.py:2981} INFO - Setting next_dagrun for Milestones3 to 2024-06-19T06:30:00+00:00, run_after=2024-06-20T06:30:00+00:00
[2024-06-30T09:30:11.348+0000] {processor.py:161} INFO - Processing /opt/airflow/dags/P2M3_devi_nirfana_DAG.py took 0.426 seconds
[2024-06-30T09:30:29.994+0000] {processor.py:153} INFO - Started process (PID=207) to work on /opt/airflow/dags/P2M3_devi_nirfana_DAG.py
[2024-06-30T09:30:29.995+0000] {processor.py:640} INFO - Processing file /opt/airflow/dags/P2M3_devi_nirfana_DAG.py for tasks to queue
[2024-06-30T09:30:29.996+0000] {logging_mixin.py:115} INFO - [2024-06-30T09:30:29.996+0000] {dagbag.py:508} INFO - Filling up the DagBag from /opt/airflow/dags/P2M3_devi_nirfana_DAG.py
[2024-06-30T09:30:30.403+0000] {processor.py:650} INFO - DAG(s) dict_keys(['Milestones3']) retrieved from /opt/airflow/dags/P2M3_devi_nirfana_DAG.py
[2024-06-30T09:30:30.427+0000] {logging_mixin.py:115} INFO - [2024-06-30T09:30:30.426+0000] {dag.py:2429} INFO - Sync 1 DAGs
[2024-06-30T09:30:30.448+0000] {logging_mixin.py:115} INFO - [2024-06-30T09:30:30.448+0000] {dag.py:2981} INFO - Setting next_dagrun for Milestones3 to 2024-06-19T06:30:00+00:00, run_after=2024-06-20T06:30:00+00:00
[2024-06-30T09:30:30.464+0000] {processor.py:161} INFO - Processing /opt/airflow/dags/P2M3_devi_nirfana_DAG.py took 0.475 seconds
[2024-06-30T09:30:36.445+0000] {processor.py:153} INFO - Started process (PID=213) to work on /opt/airflow/dags/P2M3_devi_nirfana_DAG.py
[2024-06-30T09:30:36.446+0000] {processor.py:640} INFO - Processing file /opt/airflow/dags/P2M3_devi_nirfana_DAG.py for tasks to queue
[2024-06-30T09:30:36.447+0000] {logging_mixin.py:115} INFO - [2024-06-30T09:30:36.447+0000] {dagbag.py:508} INFO - Filling up the DagBag from /opt/airflow/dags/P2M3_devi_nirfana_DAG.py
[2024-06-30T09:30:36.833+0000] {processor.py:650} INFO - DAG(s) dict_keys(['Milestones3']) retrieved from /opt/airflow/dags/P2M3_devi_nirfana_DAG.py
[2024-06-30T09:30:36.856+0000] {logging_mixin.py:115} INFO - [2024-06-30T09:30:36.856+0000] {dag.py:2429} INFO - Sync 1 DAGs
[2024-06-30T09:30:36.876+0000] {logging_mixin.py:115} INFO - [2024-06-30T09:30:36.876+0000] {dag.py:2981} INFO - Setting next_dagrun for Milestones3 to 2024-06-19T06:30:00+00:00, run_after=2024-06-20T06:30:00+00:00
[2024-06-30T09:30:36.892+0000] {processor.py:161} INFO - Processing /opt/airflow/dags/P2M3_devi_nirfana_DAG.py took 0.450 seconds
[2024-06-30T09:30:52.581+0000] {processor.py:153} INFO - Started process (PID=219) to work on /opt/airflow/dags/P2M3_devi_nirfana_DAG.py
[2024-06-30T09:30:52.584+0000] {processor.py:640} INFO - Processing file /opt/airflow/dags/P2M3_devi_nirfana_DAG.py for tasks to queue
[2024-06-30T09:30:52.586+0000] {logging_mixin.py:115} INFO - [2024-06-30T09:30:52.586+0000] {dagbag.py:508} INFO - Filling up the DagBag from /opt/airflow/dags/P2M3_devi_nirfana_DAG.py
[2024-06-30T09:30:53.044+0000] {processor.py:650} INFO - DAG(s) dict_keys(['Automate']) retrieved from /opt/airflow/dags/P2M3_devi_nirfana_DAG.py
[2024-06-30T09:30:53.135+0000] {logging_mixin.py:115} INFO - [2024-06-30T09:30:53.135+0000] {manager.py:508} INFO - Created Permission View: can read on DAG:Automate
[2024-06-30T09:30:53.149+0000] {logging_mixin.py:115} INFO - [2024-06-30T09:30:53.149+0000] {manager.py:508} INFO - Created Permission View: can edit on DAG:Automate
[2024-06-30T09:30:53.161+0000] {logging_mixin.py:115} INFO - [2024-06-30T09:30:53.160+0000] {manager.py:508} INFO - Created Permission View: can delete on DAG:Automate
[2024-06-30T09:30:53.161+0000] {logging_mixin.py:115} INFO - [2024-06-30T09:30:53.161+0000] {dag.py:2429} INFO - Sync 1 DAGs
[2024-06-30T09:30:53.171+0000] {logging_mixin.py:115} INFO - [2024-06-30T09:30:53.171+0000] {dag.py:2448} INFO - Creating ORM DAG for Automate
[2024-06-30T09:30:53.188+0000] {logging_mixin.py:115} INFO - [2024-06-30T09:30:53.187+0000] {dag.py:2981} INFO - Setting next_dagrun for Automate to 2024-06-19T06:30:00+00:00, run_after=2024-06-20T06:30:00+00:00
[2024-06-30T09:30:53.208+0000] {processor.py:161} INFO - Processing /opt/airflow/dags/P2M3_devi_nirfana_DAG.py took 0.632 seconds
[2024-06-30T09:30:54.971+0000] {processor.py:153} INFO - Started process (PID=225) to work on /opt/airflow/dags/P2M3_devi_nirfana_DAG.py
[2024-06-30T09:30:54.973+0000] {processor.py:640} INFO - Processing file /opt/airflow/dags/P2M3_devi_nirfana_DAG.py for tasks to queue
[2024-06-30T09:30:54.974+0000] {logging_mixin.py:115} INFO - [2024-06-30T09:30:54.974+0000] {dagbag.py:508} INFO - Filling up the DagBag from /opt/airflow/dags/P2M3_devi_nirfana_DAG.py
[2024-06-30T09:30:55.381+0000] {processor.py:650} INFO - DAG(s) dict_keys(['Automate_cleaning']) retrieved from /opt/airflow/dags/P2M3_devi_nirfana_DAG.py
[2024-06-30T09:30:55.448+0000] {logging_mixin.py:115} INFO - [2024-06-30T09:30:55.448+0000] {manager.py:508} INFO - Created Permission View: can read on DAG:Automate_cleaning
[2024-06-30T09:30:55.458+0000] {logging_mixin.py:115} INFO - [2024-06-30T09:30:55.458+0000] {manager.py:508} INFO - Created Permission View: can edit on DAG:Automate_cleaning
[2024-06-30T09:30:55.466+0000] {logging_mixin.py:115} INFO - [2024-06-30T09:30:55.465+0000] {manager.py:508} INFO - Created Permission View: can delete on DAG:Automate_cleaning
[2024-06-30T09:30:55.466+0000] {logging_mixin.py:115} INFO - [2024-06-30T09:30:55.466+0000] {dag.py:2429} INFO - Sync 1 DAGs
[2024-06-30T09:30:55.474+0000] {logging_mixin.py:115} INFO - [2024-06-30T09:30:55.474+0000] {dag.py:2448} INFO - Creating ORM DAG for Automate_cleaning
[2024-06-30T09:30:55.488+0000] {logging_mixin.py:115} INFO - [2024-06-30T09:30:55.488+0000] {dag.py:2981} INFO - Setting next_dagrun for Automate_cleaning to 2024-06-19T06:30:00+00:00, run_after=2024-06-20T06:30:00+00:00
[2024-06-30T09:30:55.503+0000] {processor.py:161} INFO - Processing /opt/airflow/dags/P2M3_devi_nirfana_DAG.py took 0.537 seconds
[2024-06-30T09:31:00.288+0000] {processor.py:153} INFO - Started process (PID=231) to work on /opt/airflow/dags/P2M3_devi_nirfana_DAG.py
[2024-06-30T09:31:00.290+0000] {processor.py:640} INFO - Processing file /opt/airflow/dags/P2M3_devi_nirfana_DAG.py for tasks to queue
[2024-06-30T09:31:00.291+0000] {logging_mixin.py:115} INFO - [2024-06-30T09:31:00.291+0000] {dagbag.py:508} INFO - Filling up the DagBag from /opt/airflow/dags/P2M3_devi_nirfana_DAG.py
[2024-06-30T09:31:00.737+0000] {processor.py:650} INFO - DAG(s) dict_keys(['Automate_cleaning']) retrieved from /opt/airflow/dags/P2M3_devi_nirfana_DAG.py
[2024-06-30T09:31:00.752+0000] {logging_mixin.py:115} INFO - [2024-06-30T09:31:00.751+0000] {dag.py:2429} INFO - Sync 1 DAGs
[2024-06-30T09:31:00.775+0000] {logging_mixin.py:115} INFO - [2024-06-30T09:31:00.775+0000] {dag.py:2981} INFO - Setting next_dagrun for Automate_cleaning to 2024-06-19T06:30:00+00:00, run_after=2024-06-20T06:30:00+00:00
[2024-06-30T09:31:00.789+0000] {processor.py:161} INFO - Processing /opt/airflow/dags/P2M3_devi_nirfana_DAG.py took 0.504 seconds
[2024-06-30T09:31:02.566+0000] {processor.py:153} INFO - Started process (PID=237) to work on /opt/airflow/dags/P2M3_devi_nirfana_DAG.py
[2024-06-30T09:31:02.568+0000] {processor.py:640} INFO - Processing file /opt/airflow/dags/P2M3_devi_nirfana_DAG.py for tasks to queue
[2024-06-30T09:31:02.569+0000] {logging_mixin.py:115} INFO - [2024-06-30T09:31:02.569+0000] {dagbag.py:508} INFO - Filling up the DagBag from /opt/airflow/dags/P2M3_devi_nirfana_DAG.py
[2024-06-30T09:31:03.020+0000] {processor.py:650} INFO - DAG(s) dict_keys(['Automate_cleaning']) retrieved from /opt/airflow/dags/P2M3_devi_nirfana_DAG.py
[2024-06-30T09:31:03.037+0000] {logging_mixin.py:115} INFO - [2024-06-30T09:31:03.036+0000] {dag.py:2429} INFO - Sync 1 DAGs
[2024-06-30T09:31:03.059+0000] {logging_mixin.py:115} INFO - [2024-06-30T09:31:03.059+0000] {dag.py:2981} INFO - Setting next_dagrun for Automate_cleaning to 2024-06-19T06:30:00+00:00, run_after=2024-06-20T06:30:00+00:00
[2024-06-30T09:31:03.073+0000] {processor.py:161} INFO - Processing /opt/airflow/dags/P2M3_devi_nirfana_DAG.py took 0.511 seconds
