[2024-06-30T09:39:00.241+0000] {taskinstance.py:1171} INFO - Dependencies all met for <TaskInstance: Automate_cleaning.fetch_raw_data scheduled__2024-06-24T06:30:00+00:00 [queued]>
[2024-06-30T09:39:00.383+0000] {taskinstance.py:1171} INFO - Dependencies all met for <TaskInstance: Automate_cleaning.fetch_raw_data scheduled__2024-06-24T06:30:00+00:00 [queued]>
[2024-06-30T09:39:00.387+0000] {taskinstance.py:1368} INFO - 
--------------------------------------------------------------------------------
[2024-06-30T09:39:00.390+0000] {taskinstance.py:1369} INFO - Starting attempt 1 of 1
[2024-06-30T09:39:00.392+0000] {taskinstance.py:1370} INFO - 
--------------------------------------------------------------------------------
[2024-06-30T09:39:00.558+0000] {taskinstance.py:1389} INFO - Executing <Task(PythonOperator): fetch_raw_data> on 2024-06-24 06:30:00+00:00
[2024-06-30T09:39:00.603+0000] {standard_task_runner.py:79} INFO - Running: ['***', 'tasks', 'run', 'Automate_cleaning', 'fetch_raw_data', 'scheduled__2024-06-24T06:30:00+00:00', '--job-id', '17', '--raw', '--subdir', 'DAGS_FOLDER/automate_clean_DAG.py', '--cfg-path', '/tmp/tmphlylwfdb', '--error-file', '/tmp/tmpjnwxnc3n']
[2024-06-30T09:39:00.609+0000] {standard_task_runner.py:80} INFO - Job 17: Subtask fetch_raw_data
[2024-06-30T09:39:00.597+0000] {standard_task_runner.py:52} INFO - Started process 262 to run task
[2024-06-30T09:39:00.934+0000] {task_command.py:371} INFO - Running <TaskInstance: Automate_cleaning.fetch_raw_data scheduled__2024-06-24T06:30:00+00:00 [running]> on host 3e5e5d011624
[2024-06-30T09:39:01.417+0000] {taskinstance.py:1583} INFO - Exporting the following env vars:
AIRFLOW_CTX_DAG_OWNER=devi_nirfana
AIRFLOW_CTX_DAG_ID=Automate_cleaning
AIRFLOW_CTX_TASK_ID=fetch_raw_data
AIRFLOW_CTX_EXECUTION_DATE=2024-06-24T06:30:00+00:00
AIRFLOW_CTX_TRY_NUMBER=1
AIRFLOW_CTX_DAG_RUN_ID=scheduled__2024-06-24T06:30:00+00:00
[2024-06-30T09:39:01.444+0000] {taskinstance.py:1902} ERROR - Task failed with exception
Traceback (most recent call last):
  File "/home/airflow/.local/lib/python3.7/site-packages/sqlalchemy/engine/base.py", line 1803, in _execute_context
    cursor, statement, parameters, context
  File "/home/airflow/.local/lib/python3.7/site-packages/sqlalchemy/engine/default.py", line 719, in do_execute
    cursor.execute(statement, parameters)
psycopg2.errors.SyntaxError: syntax error at or near "-"
LINE 1: SELECT * FROM fraud-data-table
                           ^


The above exception was the direct cause of the following exception:

Traceback (most recent call last):
  File "/home/airflow/.local/lib/python3.7/site-packages/airflow/operators/python.py", line 171, in execute
    return_value = self.execute_callable()
  File "/home/airflow/.local/lib/python3.7/site-packages/airflow/operators/python.py", line 189, in execute_callable
    return self.python_callable(*self.op_args, **self.op_kwargs)
  File "/opt/airflow/dags/automate_clean_DAG.py", line 60, in fetch_from_postgres
    df = pd.read_sql_query('SELECT * FROM fraud-data-table', conn)
  File "/home/airflow/.local/lib/python3.7/site-packages/pandas/io/sql.py", line 443, in read_sql_query
    dtype=dtype,
  File "/home/airflow/.local/lib/python3.7/site-packages/pandas/io/sql.py", line 1579, in read_query
    result = self.execute(*args)
  File "/home/airflow/.local/lib/python3.7/site-packages/pandas/io/sql.py", line 1424, in execute
    return self.connectable.execution_options().execute(*args, **kwargs)
  File "/home/airflow/.local/lib/python3.7/site-packages/sqlalchemy/engine/base.py", line 1279, in execute
    future=False,
  File "/home/airflow/.local/lib/python3.7/site-packages/sqlalchemy/engine/base.py", line 1585, in _exec_driver_sql
    distilled_parameters,
  File "/home/airflow/.local/lib/python3.7/site-packages/sqlalchemy/engine/base.py", line 1846, in _execute_context
    e, statement, parameters, cursor, context
  File "/home/airflow/.local/lib/python3.7/site-packages/sqlalchemy/engine/base.py", line 2027, in _handle_dbapi_exception
    sqlalchemy_exception, with_traceback=exc_info[2], from_=e
  File "/home/airflow/.local/lib/python3.7/site-packages/sqlalchemy/util/compat.py", line 207, in raise_
    raise exception
  File "/home/airflow/.local/lib/python3.7/site-packages/sqlalchemy/engine/base.py", line 1803, in _execute_context
    cursor, statement, parameters, context
  File "/home/airflow/.local/lib/python3.7/site-packages/sqlalchemy/engine/default.py", line 719, in do_execute
    cursor.execute(statement, parameters)
sqlalchemy.exc.ProgrammingError: (psycopg2.errors.SyntaxError) syntax error at or near "-"
LINE 1: SELECT * FROM fraud-data-table
                           ^

[SQL: SELECT * FROM fraud-data-table]
(Background on this error at: https://sqlalche.me/e/14/f405)
[2024-06-30T09:39:01.572+0000] {taskinstance.py:1412} INFO - Marking task as FAILED. dag_id=Automate_cleaning, task_id=fetch_raw_data, execution_date=20240624T063000, start_date=20240630T093900, end_date=20240630T093901
[2024-06-30T09:39:01.643+0000] {standard_task_runner.py:97} ERROR - Failed to execute job 17 for task fetch_raw_data ((psycopg2.errors.SyntaxError) syntax error at or near "-"
LINE 1: SELECT * FROM fraud-data-table
                           ^

[SQL: SELECT * FROM fraud-data-table]
(Background on this error at: https://sqlalche.me/e/14/f405); 262)
[2024-06-30T09:39:01.736+0000] {local_task_job.py:156} INFO - Task exited with return code 1
[2024-06-30T09:39:01.961+0000] {local_task_job.py:279} INFO - 0 downstream tasks scheduled from follow-on schedule check
[2024-06-30T09:56:42.206+0000] {taskinstance.py:1171} INFO - Dependencies all met for <TaskInstance: Automate_cleaning.fetch_raw_data scheduled__2024-06-24T06:30:00+00:00 [queued]>
[2024-06-30T09:56:42.298+0000] {taskinstance.py:1171} INFO - Dependencies all met for <TaskInstance: Automate_cleaning.fetch_raw_data scheduled__2024-06-24T06:30:00+00:00 [queued]>
[2024-06-30T09:56:42.302+0000] {taskinstance.py:1368} INFO - 
--------------------------------------------------------------------------------
[2024-06-30T09:56:42.303+0000] {taskinstance.py:1369} INFO - Starting attempt 1 of 1
[2024-06-30T09:56:42.303+0000] {taskinstance.py:1370} INFO - 
--------------------------------------------------------------------------------
[2024-06-30T09:56:42.352+0000] {taskinstance.py:1389} INFO - Executing <Task(PythonOperator): fetch_raw_data> on 2024-06-24 06:30:00+00:00
[2024-06-30T09:56:42.359+0000] {standard_task_runner.py:52} INFO - Started process 391 to run task
[2024-06-30T09:56:42.375+0000] {standard_task_runner.py:79} INFO - Running: ['***', 'tasks', 'run', 'Automate_cleaning', 'fetch_raw_data', 'scheduled__2024-06-24T06:30:00+00:00', '--job-id', '21', '--raw', '--subdir', 'DAGS_FOLDER/automate_clean_DAG.py', '--cfg-path', '/tmp/tmppcg0wajg', '--error-file', '/tmp/tmpwvk8n9gc']
[2024-06-30T09:56:42.380+0000] {standard_task_runner.py:80} INFO - Job 21: Subtask fetch_raw_data
[2024-06-30T09:56:42.579+0000] {task_command.py:371} INFO - Running <TaskInstance: Automate_cleaning.fetch_raw_data scheduled__2024-06-24T06:30:00+00:00 [running]> on host 80cef885917b
[2024-06-30T09:56:42.961+0000] {taskinstance.py:1583} INFO - Exporting the following env vars:
AIRFLOW_CTX_DAG_OWNER=devi_nirfana
AIRFLOW_CTX_DAG_ID=Automate_cleaning
AIRFLOW_CTX_TASK_ID=fetch_raw_data
AIRFLOW_CTX_EXECUTION_DATE=2024-06-24T06:30:00+00:00
AIRFLOW_CTX_TRY_NUMBER=1
AIRFLOW_CTX_DAG_RUN_ID=scheduled__2024-06-24T06:30:00+00:00
[2024-06-30T09:56:42.973+0000] {taskinstance.py:1902} ERROR - Task failed with exception
Traceback (most recent call last):
  File "/home/airflow/.local/lib/python3.7/site-packages/sqlalchemy/engine/base.py", line 1803, in _execute_context
    cursor, statement, parameters, context
  File "/home/airflow/.local/lib/python3.7/site-packages/sqlalchemy/engine/default.py", line 719, in do_execute
    cursor.execute(statement, parameters)
psycopg2.errors.SyntaxError: syntax error at or near "-"
LINE 1: SELECT * FROM fraud-data-table
                           ^


The above exception was the direct cause of the following exception:

Traceback (most recent call last):
  File "/home/airflow/.local/lib/python3.7/site-packages/airflow/operators/python.py", line 171, in execute
    return_value = self.execute_callable()
  File "/home/airflow/.local/lib/python3.7/site-packages/airflow/operators/python.py", line 189, in execute_callable
    return self.python_callable(*self.op_args, **self.op_kwargs)
  File "/opt/airflow/dags/automate_clean_DAG.py", line 60, in fetch_from_postgres
    df = pd.read_sql_query('SELECT * FROM fraud-data-table', conn)
  File "/home/airflow/.local/lib/python3.7/site-packages/pandas/io/sql.py", line 443, in read_sql_query
    dtype=dtype,
  File "/home/airflow/.local/lib/python3.7/site-packages/pandas/io/sql.py", line 1579, in read_query
    result = self.execute(*args)
  File "/home/airflow/.local/lib/python3.7/site-packages/pandas/io/sql.py", line 1424, in execute
    return self.connectable.execution_options().execute(*args, **kwargs)
  File "/home/airflow/.local/lib/python3.7/site-packages/sqlalchemy/engine/base.py", line 1279, in execute
    future=False,
  File "/home/airflow/.local/lib/python3.7/site-packages/sqlalchemy/engine/base.py", line 1585, in _exec_driver_sql
    distilled_parameters,
  File "/home/airflow/.local/lib/python3.7/site-packages/sqlalchemy/engine/base.py", line 1846, in _execute_context
    e, statement, parameters, cursor, context
  File "/home/airflow/.local/lib/python3.7/site-packages/sqlalchemy/engine/base.py", line 2027, in _handle_dbapi_exception
    sqlalchemy_exception, with_traceback=exc_info[2], from_=e
  File "/home/airflow/.local/lib/python3.7/site-packages/sqlalchemy/util/compat.py", line 207, in raise_
    raise exception
  File "/home/airflow/.local/lib/python3.7/site-packages/sqlalchemy/engine/base.py", line 1803, in _execute_context
    cursor, statement, parameters, context
  File "/home/airflow/.local/lib/python3.7/site-packages/sqlalchemy/engine/default.py", line 719, in do_execute
    cursor.execute(statement, parameters)
sqlalchemy.exc.ProgrammingError: (psycopg2.errors.SyntaxError) syntax error at or near "-"
LINE 1: SELECT * FROM fraud-data-table
                           ^

[SQL: SELECT * FROM fraud-data-table]
(Background on this error at: https://sqlalche.me/e/14/f405)
[2024-06-30T09:56:43.014+0000] {taskinstance.py:1412} INFO - Marking task as FAILED. dag_id=Automate_cleaning, task_id=fetch_raw_data, execution_date=20240624T063000, start_date=20240630T095642, end_date=20240630T095643
[2024-06-30T09:56:43.046+0000] {standard_task_runner.py:97} ERROR - Failed to execute job 21 for task fetch_raw_data ((psycopg2.errors.SyntaxError) syntax error at or near "-"
LINE 1: SELECT * FROM fraud-data-table
                           ^

[SQL: SELECT * FROM fraud-data-table]
(Background on this error at: https://sqlalche.me/e/14/f405); 391)
[2024-06-30T09:56:43.094+0000] {local_task_job.py:156} INFO - Task exited with return code 1
[2024-06-30T09:56:43.564+0000] {local_task_job.py:279} INFO - 0 downstream tasks scheduled from follow-on schedule check
