[2024-06-30T09:33:40.538+0000] {taskinstance.py:1171} INFO - Dependencies all met for <TaskInstance: Automate_cleaning.load_raw_data scheduled__2024-06-28T06:30:00+00:00 [queued]>
[2024-06-30T09:33:40.607+0000] {taskinstance.py:1171} INFO - Dependencies all met for <TaskInstance: Automate_cleaning.load_raw_data scheduled__2024-06-28T06:30:00+00:00 [queued]>
[2024-06-30T09:33:40.608+0000] {taskinstance.py:1368} INFO - 
--------------------------------------------------------------------------------
[2024-06-30T09:33:40.608+0000] {taskinstance.py:1369} INFO - Starting attempt 1 of 1
[2024-06-30T09:33:40.609+0000] {taskinstance.py:1370} INFO - 
--------------------------------------------------------------------------------
[2024-06-30T09:33:40.659+0000] {taskinstance.py:1389} INFO - Executing <Task(PythonOperator): load_raw_data> on 2024-06-28 06:30:00+00:00
[2024-06-30T09:33:40.676+0000] {standard_task_runner.py:52} INFO - Started process 234 to run task
[2024-06-30T09:33:40.711+0000] {standard_task_runner.py:79} INFO - Running: ['***', 'tasks', 'run', 'Automate_cleaning', 'load_raw_data', 'scheduled__2024-06-28T06:30:00+00:00', '--job-id', '12', '--raw', '--subdir', 'DAGS_FOLDER/automate_clean_DAG.py', '--cfg-path', '/tmp/tmpkojyxsf8', '--error-file', '/tmp/tmpajjtkpua']
[2024-06-30T09:33:40.725+0000] {standard_task_runner.py:80} INFO - Job 12: Subtask load_raw_data
[2024-06-30T09:33:40.931+0000] {task_command.py:371} INFO - Running <TaskInstance: Automate_cleaning.load_raw_data scheduled__2024-06-28T06:30:00+00:00 [running]> on host 7ad299a7fc17
[2024-06-30T09:33:41.359+0000] {taskinstance.py:1583} INFO - Exporting the following env vars:
AIRFLOW_CTX_DAG_OWNER=devi_nirfana
AIRFLOW_CTX_DAG_ID=Automate_cleaning
AIRFLOW_CTX_TASK_ID=load_raw_data
AIRFLOW_CTX_EXECUTION_DATE=2024-06-28T06:30:00+00:00
AIRFLOW_CTX_TRY_NUMBER=1
AIRFLOW_CTX_DAG_RUN_ID=scheduled__2024-06-28T06:30:00+00:00
[2024-06-30T09:33:43.089+0000] {taskinstance.py:1902} ERROR - Task failed with exception
Traceback (most recent call last):
  File "/home/airflow/.local/lib/python3.7/site-packages/sqlalchemy/engine/base.py", line 1803, in _execute_context
    cursor, statement, parameters, context
  File "/home/airflow/.local/lib/python3.7/site-packages/sqlalchemy/engine/default.py", line 719, in do_execute
    cursor.execute(statement, parameters)
psycopg2.errors.UndefinedTable: table "fraud_data" does not exist


The above exception was the direct cause of the following exception:

Traceback (most recent call last):
  File "/home/airflow/.local/lib/python3.7/site-packages/airflow/operators/python.py", line 171, in execute
    return_value = self.execute_callable()
  File "/home/airflow/.local/lib/python3.7/site-packages/airflow/operators/python.py", line 189, in execute_callable
    return self.python_callable(*self.op_args, **self.op_kwargs)
  File "/opt/airflow/dags/automate_clean_DAG.py", line 44, in load_to_postgres
    df.to_sql('fraud_data', conn, index=False, if_exists='replace')
  File "/home/airflow/.local/lib/python3.7/site-packages/pandas/core/generic.py", line 2882, in to_sql
    method=method,
  File "/home/airflow/.local/lib/python3.7/site-packages/pandas/io/sql.py", line 728, in to_sql
    **engine_kwargs,
  File "/home/airflow/.local/lib/python3.7/site-packages/pandas/io/sql.py", line 1758, in to_sql
    dtype=dtype,
  File "/home/airflow/.local/lib/python3.7/site-packages/pandas/io/sql.py", line 1650, in prep_table
    table.create()
  File "/home/airflow/.local/lib/python3.7/site-packages/pandas/io/sql.py", line 860, in create
    self.pd_sql.drop_table(self.name, self.schema)
  File "/home/airflow/.local/lib/python3.7/site-packages/pandas/io/sql.py", line 1810, in drop_table
    self.get_table(table_name, schema).drop()
  File "/home/airflow/.local/lib/python3.7/site-packages/sqlalchemy/sql/schema.py", line 967, in drop
    bind._run_ddl_visitor(ddl.SchemaDropper, self, checkfirst=checkfirst)
  File "/home/airflow/.local/lib/python3.7/site-packages/sqlalchemy/engine/base.py", line 2113, in _run_ddl_visitor
    visitorcallable(self.dialect, self, **kwargs).traverse_single(element)
  File "/home/airflow/.local/lib/python3.7/site-packages/sqlalchemy/sql/visitors.py", line 524, in traverse_single
    return meth(obj, **kw)
  File "/home/airflow/.local/lib/python3.7/site-packages/sqlalchemy/sql/ddl.py", line 1097, in visit_table
    self.connection.execute(DropTable(table))
  File "/home/airflow/.local/lib/python3.7/site-packages/sqlalchemy/engine/base.py", line 1289, in execute
    return meth(self, multiparams, params, _EMPTY_EXECUTION_OPTS)
  File "/home/airflow/.local/lib/python3.7/site-packages/sqlalchemy/sql/ddl.py", line 78, in _execute_on_connection
    self, multiparams, params, execution_options
  File "/home/airflow/.local/lib/python3.7/site-packages/sqlalchemy/engine/base.py", line 1387, in _execute_ddl
    compiled,
  File "/home/airflow/.local/lib/python3.7/site-packages/sqlalchemy/engine/base.py", line 1846, in _execute_context
    e, statement, parameters, cursor, context
  File "/home/airflow/.local/lib/python3.7/site-packages/sqlalchemy/engine/base.py", line 2027, in _handle_dbapi_exception
    sqlalchemy_exception, with_traceback=exc_info[2], from_=e
  File "/home/airflow/.local/lib/python3.7/site-packages/sqlalchemy/util/compat.py", line 207, in raise_
    raise exception
  File "/home/airflow/.local/lib/python3.7/site-packages/sqlalchemy/engine/base.py", line 1803, in _execute_context
    cursor, statement, parameters, context
  File "/home/airflow/.local/lib/python3.7/site-packages/sqlalchemy/engine/default.py", line 719, in do_execute
    cursor.execute(statement, parameters)
sqlalchemy.exc.ProgrammingError: (psycopg2.errors.UndefinedTable) table "fraud_data" does not exist

[SQL: 
DROP TABLE fraud_data]
(Background on this error at: https://sqlalche.me/e/14/f405)
[2024-06-30T09:33:43.151+0000] {taskinstance.py:1412} INFO - Marking task as FAILED. dag_id=Automate_cleaning, task_id=load_raw_data, execution_date=20240628T063000, start_date=20240630T093340, end_date=20240630T093343
[2024-06-30T09:33:43.547+0000] {standard_task_runner.py:97} ERROR - Failed to execute job 12 for task load_raw_data ((psycopg2.errors.UndefinedTable) table "fraud_data" does not exist

[SQL: 
DROP TABLE fraud_data]
(Background on this error at: https://sqlalche.me/e/14/f405); 234)
[2024-06-30T09:33:43.628+0000] {local_task_job.py:156} INFO - Task exited with return code 1
[2024-06-30T09:33:43.788+0000] {local_task_job.py:279} INFO - 0 downstream tasks scheduled from follow-on schedule check
[2024-06-30T09:38:26.349+0000] {taskinstance.py:1171} INFO - Dependencies all met for <TaskInstance: Automate_cleaning.load_raw_data scheduled__2024-06-28T06:30:00+00:00 [queued]>
[2024-06-30T09:38:26.388+0000] {taskinstance.py:1171} INFO - Dependencies all met for <TaskInstance: Automate_cleaning.load_raw_data scheduled__2024-06-28T06:30:00+00:00 [queued]>
[2024-06-30T09:38:26.391+0000] {taskinstance.py:1368} INFO - 
--------------------------------------------------------------------------------
[2024-06-30T09:38:26.391+0000] {taskinstance.py:1369} INFO - Starting attempt 1 of 1
[2024-06-30T09:38:26.395+0000] {taskinstance.py:1370} INFO - 
--------------------------------------------------------------------------------
[2024-06-30T09:38:26.463+0000] {taskinstance.py:1389} INFO - Executing <Task(PythonOperator): load_raw_data> on 2024-06-28 06:30:00+00:00
[2024-06-30T09:38:26.472+0000] {standard_task_runner.py:52} INFO - Started process 228 to run task
[2024-06-30T09:38:26.489+0000] {standard_task_runner.py:79} INFO - Running: ['***', 'tasks', 'run', 'Automate_cleaning', 'load_raw_data', 'scheduled__2024-06-28T06:30:00+00:00', '--job-id', '12', '--raw', '--subdir', 'DAGS_FOLDER/automate_clean_DAG.py', '--cfg-path', '/tmp/tmp6urlo840', '--error-file', '/tmp/tmp62vbbrjy']
[2024-06-30T09:38:26.500+0000] {standard_task_runner.py:80} INFO - Job 12: Subtask load_raw_data
[2024-06-30T09:38:26.610+0000] {task_command.py:371} INFO - Running <TaskInstance: Automate_cleaning.load_raw_data scheduled__2024-06-28T06:30:00+00:00 [running]> on host 3e5e5d011624
[2024-06-30T09:38:26.724+0000] {taskinstance.py:1583} INFO - Exporting the following env vars:
AIRFLOW_CTX_DAG_OWNER=devi_nirfana
AIRFLOW_CTX_DAG_ID=Automate_cleaning
AIRFLOW_CTX_TASK_ID=load_raw_data
AIRFLOW_CTX_EXECUTION_DATE=2024-06-28T06:30:00+00:00
AIRFLOW_CTX_TRY_NUMBER=1
AIRFLOW_CTX_DAG_RUN_ID=scheduled__2024-06-28T06:30:00+00:00
[2024-06-30T09:38:56.354+0000] {python.py:173} INFO - Done. Returned value was: None
[2024-06-30T09:38:56.824+0000] {taskinstance.py:1412} INFO - Marking task as SUCCESS. dag_id=Automate_cleaning, task_id=load_raw_data, execution_date=20240628T063000, start_date=20240630T093826, end_date=20240630T093856
[2024-06-30T09:38:56.964+0000] {local_task_job.py:156} INFO - Task exited with return code 0
[2024-06-30T09:38:57.137+0000] {local_task_job.py:279} INFO - 1 downstream tasks scheduled from follow-on schedule check
[2024-06-30T09:56:03.782+0000] {taskinstance.py:1171} INFO - Dependencies all met for <TaskInstance: Automate_cleaning.load_raw_data scheduled__2024-06-28T06:30:00+00:00 [queued]>
[2024-06-30T09:56:03.837+0000] {taskinstance.py:1171} INFO - Dependencies all met for <TaskInstance: Automate_cleaning.load_raw_data scheduled__2024-06-28T06:30:00+00:00 [queued]>
[2024-06-30T09:56:03.844+0000] {taskinstance.py:1368} INFO - 
--------------------------------------------------------------------------------
[2024-06-30T09:56:03.844+0000] {taskinstance.py:1369} INFO - Starting attempt 1 of 1
[2024-06-30T09:56:03.845+0000] {taskinstance.py:1370} INFO - 
--------------------------------------------------------------------------------
[2024-06-30T09:56:03.959+0000] {taskinstance.py:1389} INFO - Executing <Task(PythonOperator): load_raw_data> on 2024-06-28 06:30:00+00:00
[2024-06-30T09:56:03.995+0000] {standard_task_runner.py:52} INFO - Started process 358 to run task
[2024-06-30T09:56:04.019+0000] {standard_task_runner.py:79} INFO - Running: ['***', 'tasks', 'run', 'Automate_cleaning', 'load_raw_data', 'scheduled__2024-06-28T06:30:00+00:00', '--job-id', '13', '--raw', '--subdir', 'DAGS_FOLDER/automate_clean_DAG.py', '--cfg-path', '/tmp/tmp873ymahq', '--error-file', '/tmp/tmp1qeyj2k2']
[2024-06-30T09:56:04.026+0000] {standard_task_runner.py:80} INFO - Job 13: Subtask load_raw_data
[2024-06-30T09:56:04.424+0000] {task_command.py:371} INFO - Running <TaskInstance: Automate_cleaning.load_raw_data scheduled__2024-06-28T06:30:00+00:00 [running]> on host 80cef885917b
[2024-06-30T09:56:04.898+0000] {taskinstance.py:1583} INFO - Exporting the following env vars:
AIRFLOW_CTX_DAG_OWNER=devi_nirfana
AIRFLOW_CTX_DAG_ID=Automate_cleaning
AIRFLOW_CTX_TASK_ID=load_raw_data
AIRFLOW_CTX_EXECUTION_DATE=2024-06-28T06:30:00+00:00
AIRFLOW_CTX_TRY_NUMBER=1
AIRFLOW_CTX_DAG_RUN_ID=scheduled__2024-06-28T06:30:00+00:00
[2024-06-30T09:56:40.819+0000] {python.py:173} INFO - Done. Returned value was: None
[2024-06-30T09:56:40.981+0000] {taskinstance.py:1412} INFO - Marking task as SUCCESS. dag_id=Automate_cleaning, task_id=load_raw_data, execution_date=20240628T063000, start_date=20240630T095603, end_date=20240630T095640
[2024-06-30T09:56:41.260+0000] {local_task_job.py:156} INFO - Task exited with return code 0
[2024-06-30T09:56:41.505+0000] {local_task_job.py:279} INFO - 0 downstream tasks scheduled from follow-on schedule check
